[2025-02-13T06:41:10.920+0000] {local_task_job_runner.py:123} INFO - ::group::Pre task execution logs
[2025-02-13T06:41:10.942+0000] {taskinstance.py:2614} INFO - Dependencies all met for dep_context=non-requeueable deps ti=<TaskInstance: transform_data_dag.dbt_run manual__2025-02-13T06:41:08.962941+00:00 [queued]>
[2025-02-13T06:41:10.953+0000] {taskinstance.py:2614} INFO - Dependencies all met for dep_context=requeueable deps ti=<TaskInstance: transform_data_dag.dbt_run manual__2025-02-13T06:41:08.962941+00:00 [queued]>
[2025-02-13T06:41:10.954+0000] {taskinstance.py:2867} INFO - Starting attempt 1 of 1
[2025-02-13T06:41:10.970+0000] {taskinstance.py:2890} INFO - Executing <Task(BashOperator): dbt_run> on 2025-02-13 06:41:08.962941+00:00
[2025-02-13T06:41:10.976+0000] {logging_mixin.py:190} WARNING - /home/airflow/.local/lib/python3.12/site-packages/airflow/task/task_runner/standard_task_runner.py:70 DeprecationWarning: This process (pid=3438) is multi-threaded, use of fork() may lead to deadlocks in the child.
[2025-02-13T06:41:10.978+0000] {standard_task_runner.py:72} INFO - Started process 3439 to run task
[2025-02-13T06:41:10.977+0000] {standard_task_runner.py:104} INFO - Running: ['airflow', 'tasks', 'run', 'transform_data_dag', 'dbt_run', 'manual__2025-02-13T06:41:08.962941+00:00', '--job-id', '34', '--raw', '--subdir', 'DAGS_FOLDER/transform_data_dag.py', '--cfg-path', '/tmp/tmpnx6ggcvl']
[2025-02-13T06:41:10.979+0000] {standard_task_runner.py:105} INFO - Job 34: Subtask dbt_run
[2025-02-13T06:41:10.998+0000] {logging_mixin.py:190} WARNING - /home/airflow/.local/lib/python3.12/site-packages/airflow/settings.py:209 DeprecationWarning: The sql_alchemy_conn option in [core] has been moved to the sql_alchemy_conn option in [database] - the old setting has been used, but please update your config.
[2025-02-13T06:41:11.033+0000] {task_command.py:467} INFO - Running <TaskInstance: transform_data_dag.dbt_run manual__2025-02-13T06:41:08.962941+00:00 [running]> on host 89bb8c6379b5
[2025-02-13T06:41:11.097+0000] {logging_mixin.py:190} WARNING - /home/airflow/.local/lib/python3.12/site-packages/airflow/utils/log/secrets_masker.py:84 DeprecationWarning: The sensitive_variable_fields option in [admin] has been moved to the sensitive_var_conn_names option in [core] - the old setting has been used, but please update your config.
[2025-02-13T06:41:11.130+0000] {taskinstance.py:3134} INFO - Exporting env vars: AIRFLOW_CTX_DAG_OWNER='airflow' AIRFLOW_CTX_DAG_ID='transform_data_dag' AIRFLOW_CTX_TASK_ID='dbt_run' AIRFLOW_CTX_EXECUTION_DATE='2025-02-13T06:41:08.962941+00:00' AIRFLOW_CTX_TRY_NUMBER='1' AIRFLOW_CTX_DAG_RUN_ID='manual__2025-02-13T06:41:08.962941+00:00'
[2025-02-13T06:41:11.131+0000] {taskinstance.py:732} INFO - ::endgroup::
[2025-02-13T06:41:11.149+0000] {subprocess.py:78} INFO - Tmp dir root location: /tmp
[2025-02-13T06:41:11.151+0000] {subprocess.py:88} INFO - Running command: ['/usr/bin/bash', '-c', 'cd /opt/airflow/dags/dbt/***_project && dbt run']
[2025-02-13T06:41:11.159+0000] {subprocess.py:99} INFO - Output:
[2025-02-13T06:41:13.517+0000] {subprocess.py:106} INFO - [0m06:41:13  Running with dbt=1.8.7
[2025-02-13T06:41:13.861+0000] {subprocess.py:106} INFO - [0m06:41:13  Registered adapter: ***=1.9.0
[2025-02-13T06:41:14.889+0000] {subprocess.py:106} INFO - [0m06:41:14  Found 4 models, 3 sources, 429 macros
[2025-02-13T06:41:14.894+0000] {subprocess.py:106} INFO - [0m06:41:14
[2025-02-13T06:41:15.019+0000] {subprocess.py:106} INFO - [0m06:41:15  Concurrency: 1 threads (target='dev')
[2025-02-13T06:41:15.020+0000] {subprocess.py:106} INFO - [0m06:41:15
[2025-02-13T06:41:15.102+0000] {subprocess.py:106} INFO - [0m06:41:15  1 of 1 START sql incremental model model.products .............................. [RUN]
[2025-02-13T06:41:15.378+0000] {subprocess.py:106} INFO - [0m06:41:15  1 of 1 ERROR creating sql incremental model model.products ..................... [[31mERROR[0m in 0.27s]
[2025-02-13T06:41:15.397+0000] {subprocess.py:106} INFO - [0m06:41:15
[2025-02-13T06:41:15.398+0000] {subprocess.py:106} INFO - [0m06:41:15  Finished running 1 incremental model in 0 hours 0 minutes and 0.50 seconds (0.50s).
[2025-02-13T06:41:15.473+0000] {subprocess.py:106} INFO - [0m06:41:15
[2025-02-13T06:41:15.474+0000] {subprocess.py:106} INFO - [0m06:41:15  [31mCompleted with 1 error and 0 warnings:[0m
[2025-02-13T06:41:15.475+0000] {subprocess.py:106} INFO - [0m06:41:15
[2025-02-13T06:41:15.476+0000] {subprocess.py:106} INFO - [0m06:41:15    Database Error in model products (models/cleansed/products.sql)
[2025-02-13T06:41:15.477+0000] {subprocess.py:106} INFO -   column "date_load" does not exist
[2025-02-13T06:41:15.478+0000] {subprocess.py:106} INFO -   LINE 5:         select "price", "date_load", "product_id", "product_...
[2025-02-13T06:41:15.478+0000] {subprocess.py:106} INFO -                                   ^
[2025-02-13T06:41:15.479+0000] {subprocess.py:106} INFO -   HINT:  There is a column named "date_load" in table "products", but it cannot be referenced from this part of the query.
[2025-02-13T06:41:15.479+0000] {subprocess.py:106} INFO -   compiled code at target/run/***_project/models/cleansed/products.sql
[2025-02-13T06:41:15.480+0000] {subprocess.py:106} INFO - [0m06:41:15
[2025-02-13T06:41:15.481+0000] {subprocess.py:106} INFO - [0m06:41:15  Done. PASS=0 WARN=0 ERROR=1 SKIP=0 TOTAL=1
[2025-02-13T06:41:16.229+0000] {subprocess.py:110} INFO - Command exited with return code 1
[2025-02-13T06:41:16.240+0000] {taskinstance.py:3313} ERROR - Task failed with exception
Traceback (most recent call last):
  File "/home/airflow/.local/lib/python3.12/site-packages/airflow/models/taskinstance.py", line 768, in _execute_task
    result = _execute_callable(context=context, **execute_callable_kwargs)
             ^^^^^^^^^^^^^^^^^^^^^^^^^^^^^^^^^^^^^^^^^^^^^^^^^^^^^^^^^^^^^
  File "/home/airflow/.local/lib/python3.12/site-packages/airflow/models/taskinstance.py", line 734, in _execute_callable
    return ExecutionCallableRunner(
           ^^^^^^^^^^^^^^^^^^^^^^^^
  File "/home/airflow/.local/lib/python3.12/site-packages/airflow/utils/operator_helpers.py", line 252, in run
    return self.func(*args, **kwargs)
           ^^^^^^^^^^^^^^^^^^^^^^^^^^
  File "/home/airflow/.local/lib/python3.12/site-packages/airflow/models/baseoperator.py", line 424, in wrapper
    return func(self, *args, **kwargs)
           ^^^^^^^^^^^^^^^^^^^^^^^^^^^
  File "/home/airflow/.local/lib/python3.12/site-packages/airflow/operators/bash.py", line 276, in execute
    raise AirflowException(
airflow.exceptions.AirflowException: Bash command failed. The command returned a non-zero exit code 1.
[2025-02-13T06:41:16.247+0000] {taskinstance.py:1226} INFO - Marking task as FAILED. dag_id=transform_data_dag, task_id=dbt_run, run_id=manual__2025-02-13T06:41:08.962941+00:00, execution_date=20250213T064108, start_date=20250213T064110, end_date=20250213T064116
[2025-02-13T06:41:16.276+0000] {taskinstance.py:341} INFO - ::group::Post task execution logs
[2025-02-13T06:41:16.277+0000] {standard_task_runner.py:124} ERROR - Failed to execute job 34 for task dbt_run (Bash command failed. The command returned a non-zero exit code 1.; 3439)
Traceback (most recent call last):
  File "/home/airflow/.local/lib/python3.12/site-packages/airflow/task/task_runner/standard_task_runner.py", line 117, in _start_by_fork
    ret = args.func(args, dag=self.dag)
          ^^^^^^^^^^^^^^^^^^^^^^^^^^^^^
  File "/home/airflow/.local/lib/python3.12/site-packages/airflow/cli/cli_config.py", line 49, in command
    return func(*args, **kwargs)
           ^^^^^^^^^^^^^^^^^^^^^
  File "/home/airflow/.local/lib/python3.12/site-packages/airflow/utils/cli.py", line 116, in wrapper
    return f(*args, **kwargs)
           ^^^^^^^^^^^^^^^^^^
  File "/home/airflow/.local/lib/python3.12/site-packages/airflow/cli/commands/task_command.py", line 483, in task_run
    task_return_code = _run_task_by_selected_method(args, _dag, ti)
                       ^^^^^^^^^^^^^^^^^^^^^^^^^^^^^^^^^^^^^^^^^^^^
  File "/home/airflow/.local/lib/python3.12/site-packages/airflow/cli/commands/task_command.py", line 256, in _run_task_by_selected_method
    return _run_raw_task(args, ti)
           ^^^^^^^^^^^^^^^^^^^^^^^
  File "/home/airflow/.local/lib/python3.12/site-packages/airflow/cli/commands/task_command.py", line 341, in _run_raw_task
    return ti._run_raw_task(
           ^^^^^^^^^^^^^^^^^
  File "/home/airflow/.local/lib/python3.12/site-packages/airflow/utils/session.py", line 97, in wrapper
    return func(*args, session=session, **kwargs)
           ^^^^^^^^^^^^^^^^^^^^^^^^^^^^^^^^^^^^^^
  File "/home/airflow/.local/lib/python3.12/site-packages/airflow/models/taskinstance.py", line 3006, in _run_raw_task
    return _run_raw_task(
           ^^^^^^^^^^^^^^
  File "/home/airflow/.local/lib/python3.12/site-packages/airflow/models/taskinstance.py", line 274, in _run_raw_task
    TaskInstance._execute_task_with_callbacks(
  File "/home/airflow/.local/lib/python3.12/site-packages/airflow/models/taskinstance.py", line 3161, in _execute_task_with_callbacks
    result = self._execute_task(context, task_orig)
             ^^^^^^^^^^^^^^^^^^^^^^^^^^^^^^^^^^^^^^
  File "/home/airflow/.local/lib/python3.12/site-packages/airflow/models/taskinstance.py", line 3185, in _execute_task
    return _execute_task(self, context, task_orig)
           ^^^^^^^^^^^^^^^^^^^^^^^^^^^^^^^^^^^^^^^
  File "/home/airflow/.local/lib/python3.12/site-packages/airflow/models/taskinstance.py", line 768, in _execute_task
    result = _execute_callable(context=context, **execute_callable_kwargs)
             ^^^^^^^^^^^^^^^^^^^^^^^^^^^^^^^^^^^^^^^^^^^^^^^^^^^^^^^^^^^^^
  File "/home/airflow/.local/lib/python3.12/site-packages/airflow/models/taskinstance.py", line 734, in _execute_callable
    return ExecutionCallableRunner(
           ^^^^^^^^^^^^^^^^^^^^^^^^
  File "/home/airflow/.local/lib/python3.12/site-packages/airflow/utils/operator_helpers.py", line 252, in run
    return self.func(*args, **kwargs)
           ^^^^^^^^^^^^^^^^^^^^^^^^^^
  File "/home/airflow/.local/lib/python3.12/site-packages/airflow/models/baseoperator.py", line 424, in wrapper
    return func(self, *args, **kwargs)
           ^^^^^^^^^^^^^^^^^^^^^^^^^^^
  File "/home/airflow/.local/lib/python3.12/site-packages/airflow/operators/bash.py", line 276, in execute
    raise AirflowException(
airflow.exceptions.AirflowException: Bash command failed. The command returned a non-zero exit code 1.
[2025-02-13T06:41:16.306+0000] {local_task_job_runner.py:266} INFO - Task exited with return code 1
[2025-02-13T06:41:16.329+0000] {taskinstance.py:3901} INFO - 0 downstream tasks scheduled from follow-on schedule check
[2025-02-13T06:41:16.346+0000] {local_task_job_runner.py:245} INFO - ::endgroup::
