[2025-02-13T07:57:26.819+0000] {local_task_job_runner.py:123} INFO - ::group::Pre task execution logs
[2025-02-13T07:57:26.845+0000] {taskinstance.py:2614} INFO - Dependencies all met for dep_context=non-requeueable deps ti=<TaskInstance: transform_data_dag.dbt_test manual__2025-02-13T07:57:25.163553+00:00 [queued]>
[2025-02-13T07:57:26.857+0000] {taskinstance.py:2614} INFO - Dependencies all met for dep_context=requeueable deps ti=<TaskInstance: transform_data_dag.dbt_test manual__2025-02-13T07:57:25.163553+00:00 [queued]>
[2025-02-13T07:57:26.858+0000] {taskinstance.py:2867} INFO - Starting attempt 1 of 1
[2025-02-13T07:57:26.871+0000] {taskinstance.py:2890} INFO - Executing <Task(BashOperator): dbt_test> on 2025-02-13 07:57:25.163553+00:00
[2025-02-13T07:57:26.878+0000] {logging_mixin.py:190} WARNING - /home/airflow/.local/lib/python3.12/site-packages/airflow/task/task_runner/standard_task_runner.py:70 DeprecationWarning: This process (pid=5268) is multi-threaded, use of fork() may lead to deadlocks in the child.
[2025-02-13T07:57:26.880+0000] {standard_task_runner.py:72} INFO - Started process 5269 to run task
[2025-02-13T07:57:26.878+0000] {standard_task_runner.py:104} INFO - Running: ['airflow', 'tasks', 'run', 'transform_data_dag', 'dbt_test', 'manual__2025-02-13T07:57:25.163553+00:00', '--job-id', '58', '--raw', '--subdir', 'DAGS_FOLDER/transform_data_dag.py', '--cfg-path', '/tmp/tmp_jwbw8e2']
[2025-02-13T07:57:26.881+0000] {standard_task_runner.py:105} INFO - Job 58: Subtask dbt_test
[2025-02-13T07:57:26.901+0000] {logging_mixin.py:190} WARNING - /home/airflow/.local/lib/python3.12/site-packages/airflow/settings.py:209 DeprecationWarning: The sql_alchemy_conn option in [core] has been moved to the sql_alchemy_conn option in [database] - the old setting has been used, but please update your config.
[2025-02-13T07:57:26.935+0000] {task_command.py:467} INFO - Running <TaskInstance: transform_data_dag.dbt_test manual__2025-02-13T07:57:25.163553+00:00 [running]> on host 89bb8c6379b5
[2025-02-13T07:57:26.995+0000] {logging_mixin.py:190} WARNING - /home/airflow/.local/lib/python3.12/site-packages/airflow/utils/log/secrets_masker.py:84 DeprecationWarning: The sensitive_variable_fields option in [admin] has been moved to the sensitive_var_conn_names option in [core] - the old setting has been used, but please update your config.
[2025-02-13T07:57:27.028+0000] {taskinstance.py:3134} INFO - Exporting env vars: AIRFLOW_CTX_DAG_OWNER='airflow' AIRFLOW_CTX_DAG_ID='transform_data_dag' AIRFLOW_CTX_TASK_ID='dbt_test' AIRFLOW_CTX_EXECUTION_DATE='2025-02-13T07:57:25.163553+00:00' AIRFLOW_CTX_TRY_NUMBER='1' AIRFLOW_CTX_DAG_RUN_ID='manual__2025-02-13T07:57:25.163553+00:00'
[2025-02-13T07:57:27.029+0000] {taskinstance.py:732} INFO - ::endgroup::
[2025-02-13T07:57:27.046+0000] {subprocess.py:78} INFO - Tmp dir root location: /tmp
[2025-02-13T07:57:27.048+0000] {subprocess.py:88} INFO - Running command: ['/usr/bin/bash', '-c', 'cd /opt/airflow/dags/dbt/***_project && dbt test']
[2025-02-13T07:57:27.056+0000] {subprocess.py:99} INFO - Output:
[2025-02-13T07:57:29.707+0000] {subprocess.py:106} INFO - [0m07:57:29  Running with dbt=1.8.7
[2025-02-13T07:57:30.029+0000] {subprocess.py:106} INFO - [0m07:57:30  Registered adapter: ***=1.9.0
[2025-02-13T07:57:30.928+0000] {subprocess.py:106} INFO - [0m07:57:30  Found 6 models, 3 data tests, 3 sources, 429 macros
[2025-02-13T07:57:30.932+0000] {subprocess.py:106} INFO - [0m07:57:30
[2025-02-13T07:57:31.063+0000] {subprocess.py:106} INFO - [0m07:57:31  Concurrency: 1 threads (target='dev')
[2025-02-13T07:57:31.064+0000] {subprocess.py:106} INFO - [0m07:57:31
[2025-02-13T07:57:31.078+0000] {subprocess.py:106} INFO - [0m07:57:31  1 of 3 START test accepted_values_sources_products_room_type__Entire_home_apt__Private_room__Shared_room__Hotel_room  [RUN]
[2025-02-13T07:57:31.202+0000] {subprocess.py:106} INFO - [0m07:57:31  1 of 3 ERROR accepted_values_sources_products_room_type__Entire_home_apt__Private_room__Shared_room__Hotel_room  [[31mERROR[0m in 0.12s]
[2025-02-13T07:57:31.206+0000] {subprocess.py:106} INFO - [0m07:57:31  2 of 3 START test not_null_sources_products_product_id ......................... [RUN]
[2025-02-13T07:57:31.266+0000] {subprocess.py:106} INFO - [0m07:57:31  2 of 3 PASS not_null_sources_products_product_id ............................... [[32mPASS[0m in 0.06s]
[2025-02-13T07:57:31.269+0000] {subprocess.py:106} INFO - [0m07:57:31  3 of 3 START test unique_sources_products_product_id ........................... [RUN]
[2025-02-13T07:57:31.329+0000] {subprocess.py:106} INFO - [0m07:57:31  3 of 3 FAIL 2 unique_sources_products_product_id ............................... [[31mFAIL 2[0m in 0.06s]
[2025-02-13T07:57:31.347+0000] {subprocess.py:106} INFO - [0m07:57:31
[2025-02-13T07:57:31.348+0000] {subprocess.py:106} INFO - [0m07:57:31  Finished running 3 data tests in 0 hours 0 minutes and 0.41 seconds (0.41s).
[2025-02-13T07:57:31.423+0000] {subprocess.py:106} INFO - [0m07:57:31
[2025-02-13T07:57:31.424+0000] {subprocess.py:106} INFO - [0m07:57:31  [31mCompleted with 2 errors and 0 warnings:[0m
[2025-02-13T07:57:31.425+0000] {subprocess.py:106} INFO - [0m07:57:31
[2025-02-13T07:57:31.426+0000] {subprocess.py:106} INFO - [0m07:57:31    Database Error in test accepted_values_sources_products_room_type__Entire_home_apt__Private_room__Shared_room__Hotel_room (models/schema.yml)
[2025-02-13T07:57:31.427+0000] {subprocess.py:106} INFO -   column "room_type" does not exist
[2025-02-13T07:57:31.427+0000] {subprocess.py:106} INFO -   LINE 25:         room_type as value_field,
[2025-02-13T07:57:31.428+0000] {subprocess.py:106} INFO -                    ^
[2025-02-13T07:57:31.428+0000] {subprocess.py:106} INFO -   compiled code at target/run/***_project/models/schema.yml/accepted_values_sources_produc_60dd6f8a473756f6777a903c9ec1640b.sql
[2025-02-13T07:57:31.429+0000] {subprocess.py:106} INFO - [0m07:57:31
[2025-02-13T07:57:31.429+0000] {subprocess.py:106} INFO - [0m07:57:31  [31mFailure in test unique_sources_products_product_id (models/schema.yml)[0m
[2025-02-13T07:57:31.430+0000] {subprocess.py:106} INFO - [0m07:57:31    Got 2 results, configured to fail if != 0
[2025-02-13T07:57:31.431+0000] {subprocess.py:106} INFO - [0m07:57:31
[2025-02-13T07:57:31.431+0000] {subprocess.py:106} INFO - [0m07:57:31    compiled code at target/compiled/***_project/models/schema.yml/unique_sources_products_product_id.sql
[2025-02-13T07:57:31.432+0000] {subprocess.py:106} INFO - [0m07:57:31
[2025-02-13T07:57:31.433+0000] {subprocess.py:106} INFO - [0m07:57:31  Done. PASS=1 WARN=0 ERROR=2 SKIP=0 TOTAL=3
[2025-02-13T07:57:32.195+0000] {subprocess.py:110} INFO - Command exited with return code 1
[2025-02-13T07:57:32.209+0000] {taskinstance.py:3313} ERROR - Task failed with exception
Traceback (most recent call last):
  File "/home/airflow/.local/lib/python3.12/site-packages/airflow/models/taskinstance.py", line 768, in _execute_task
    result = _execute_callable(context=context, **execute_callable_kwargs)
             ^^^^^^^^^^^^^^^^^^^^^^^^^^^^^^^^^^^^^^^^^^^^^^^^^^^^^^^^^^^^^
  File "/home/airflow/.local/lib/python3.12/site-packages/airflow/models/taskinstance.py", line 734, in _execute_callable
    return ExecutionCallableRunner(
           ^^^^^^^^^^^^^^^^^^^^^^^^
  File "/home/airflow/.local/lib/python3.12/site-packages/airflow/utils/operator_helpers.py", line 252, in run
    return self.func(*args, **kwargs)
           ^^^^^^^^^^^^^^^^^^^^^^^^^^
  File "/home/airflow/.local/lib/python3.12/site-packages/airflow/models/baseoperator.py", line 424, in wrapper
    return func(self, *args, **kwargs)
           ^^^^^^^^^^^^^^^^^^^^^^^^^^^
  File "/home/airflow/.local/lib/python3.12/site-packages/airflow/operators/bash.py", line 276, in execute
    raise AirflowException(
airflow.exceptions.AirflowException: Bash command failed. The command returned a non-zero exit code 1.
[2025-02-13T07:57:32.216+0000] {taskinstance.py:1226} INFO - Marking task as FAILED. dag_id=transform_data_dag, task_id=dbt_test, run_id=manual__2025-02-13T07:57:25.163553+00:00, execution_date=20250213T075725, start_date=20250213T075726, end_date=20250213T075732
[2025-02-13T07:57:32.249+0000] {taskinstance.py:341} INFO - ::group::Post task execution logs
[2025-02-13T07:57:32.249+0000] {standard_task_runner.py:124} ERROR - Failed to execute job 58 for task dbt_test (Bash command failed. The command returned a non-zero exit code 1.; 5269)
Traceback (most recent call last):
  File "/home/airflow/.local/lib/python3.12/site-packages/airflow/task/task_runner/standard_task_runner.py", line 117, in _start_by_fork
    ret = args.func(args, dag=self.dag)
          ^^^^^^^^^^^^^^^^^^^^^^^^^^^^^
  File "/home/airflow/.local/lib/python3.12/site-packages/airflow/cli/cli_config.py", line 49, in command
    return func(*args, **kwargs)
           ^^^^^^^^^^^^^^^^^^^^^
  File "/home/airflow/.local/lib/python3.12/site-packages/airflow/utils/cli.py", line 116, in wrapper
    return f(*args, **kwargs)
           ^^^^^^^^^^^^^^^^^^
  File "/home/airflow/.local/lib/python3.12/site-packages/airflow/cli/commands/task_command.py", line 483, in task_run
    task_return_code = _run_task_by_selected_method(args, _dag, ti)
                       ^^^^^^^^^^^^^^^^^^^^^^^^^^^^^^^^^^^^^^^^^^^^
  File "/home/airflow/.local/lib/python3.12/site-packages/airflow/cli/commands/task_command.py", line 256, in _run_task_by_selected_method
    return _run_raw_task(args, ti)
           ^^^^^^^^^^^^^^^^^^^^^^^
  File "/home/airflow/.local/lib/python3.12/site-packages/airflow/cli/commands/task_command.py", line 341, in _run_raw_task
    return ti._run_raw_task(
           ^^^^^^^^^^^^^^^^^
  File "/home/airflow/.local/lib/python3.12/site-packages/airflow/utils/session.py", line 97, in wrapper
    return func(*args, session=session, **kwargs)
           ^^^^^^^^^^^^^^^^^^^^^^^^^^^^^^^^^^^^^^
  File "/home/airflow/.local/lib/python3.12/site-packages/airflow/models/taskinstance.py", line 3006, in _run_raw_task
    return _run_raw_task(
           ^^^^^^^^^^^^^^
  File "/home/airflow/.local/lib/python3.12/site-packages/airflow/models/taskinstance.py", line 274, in _run_raw_task
    TaskInstance._execute_task_with_callbacks(
  File "/home/airflow/.local/lib/python3.12/site-packages/airflow/models/taskinstance.py", line 3161, in _execute_task_with_callbacks
    result = self._execute_task(context, task_orig)
             ^^^^^^^^^^^^^^^^^^^^^^^^^^^^^^^^^^^^^^
  File "/home/airflow/.local/lib/python3.12/site-packages/airflow/models/taskinstance.py", line 3185, in _execute_task
    return _execute_task(self, context, task_orig)
           ^^^^^^^^^^^^^^^^^^^^^^^^^^^^^^^^^^^^^^^
  File "/home/airflow/.local/lib/python3.12/site-packages/airflow/models/taskinstance.py", line 768, in _execute_task
    result = _execute_callable(context=context, **execute_callable_kwargs)
             ^^^^^^^^^^^^^^^^^^^^^^^^^^^^^^^^^^^^^^^^^^^^^^^^^^^^^^^^^^^^^
  File "/home/airflow/.local/lib/python3.12/site-packages/airflow/models/taskinstance.py", line 734, in _execute_callable
    return ExecutionCallableRunner(
           ^^^^^^^^^^^^^^^^^^^^^^^^
  File "/home/airflow/.local/lib/python3.12/site-packages/airflow/utils/operator_helpers.py", line 252, in run
    return self.func(*args, **kwargs)
           ^^^^^^^^^^^^^^^^^^^^^^^^^^
  File "/home/airflow/.local/lib/python3.12/site-packages/airflow/models/baseoperator.py", line 424, in wrapper
    return func(self, *args, **kwargs)
           ^^^^^^^^^^^^^^^^^^^^^^^^^^^
  File "/home/airflow/.local/lib/python3.12/site-packages/airflow/operators/bash.py", line 276, in execute
    raise AirflowException(
airflow.exceptions.AirflowException: Bash command failed. The command returned a non-zero exit code 1.
[2025-02-13T07:57:32.284+0000] {local_task_job_runner.py:266} INFO - Task exited with return code 1
[2025-02-13T07:57:32.312+0000] {taskinstance.py:3901} INFO - 0 downstream tasks scheduled from follow-on schedule check
[2025-02-13T07:57:32.318+0000] {local_task_job_runner.py:245} INFO - ::endgroup::
