[2025-02-13T08:25:58.742+0000] {local_task_job_runner.py:123} INFO - ::group::Pre task execution logs
[2025-02-13T08:25:58.769+0000] {taskinstance.py:2614} INFO - Dependencies all met for dep_context=non-requeueable deps ti=<TaskInstance: transform_data_dag.dbt_test manual__2025-02-13T08:25:56.917849+00:00 [queued]>
[2025-02-13T08:25:58.781+0000] {taskinstance.py:2614} INFO - Dependencies all met for dep_context=requeueable deps ti=<TaskInstance: transform_data_dag.dbt_test manual__2025-02-13T08:25:56.917849+00:00 [queued]>
[2025-02-13T08:25:58.782+0000] {taskinstance.py:2867} INFO - Starting attempt 1 of 1
[2025-02-13T08:25:58.797+0000] {taskinstance.py:2890} INFO - Executing <Task(BashOperator): dbt_test> on 2025-02-13 08:25:56.917849+00:00
[2025-02-13T08:25:58.807+0000] {logging_mixin.py:190} WARNING - /home/airflow/.local/lib/python3.12/site-packages/airflow/task/task_runner/standard_task_runner.py:70 DeprecationWarning: This process (pid=6047) is multi-threaded, use of fork() may lead to deadlocks in the child.
[2025-02-13T08:25:58.810+0000] {standard_task_runner.py:72} INFO - Started process 6048 to run task
[2025-02-13T08:25:58.807+0000] {standard_task_runner.py:104} INFO - Running: ['airflow', 'tasks', 'run', 'transform_data_dag', 'dbt_test', 'manual__2025-02-13T08:25:56.917849+00:00', '--job-id', '74', '--raw', '--subdir', 'DAGS_FOLDER/transform_data_dag.py', '--cfg-path', '/tmp/tmpyl64oug4']
[2025-02-13T08:25:58.811+0000] {standard_task_runner.py:105} INFO - Job 74: Subtask dbt_test
[2025-02-13T08:25:58.830+0000] {logging_mixin.py:190} WARNING - /home/airflow/.local/lib/python3.12/site-packages/airflow/settings.py:209 DeprecationWarning: The sql_alchemy_conn option in [core] has been moved to the sql_alchemy_conn option in [database] - the old setting has been used, but please update your config.
[2025-02-13T08:25:58.867+0000] {task_command.py:467} INFO - Running <TaskInstance: transform_data_dag.dbt_test manual__2025-02-13T08:25:56.917849+00:00 [running]> on host 89bb8c6379b5
[2025-02-13T08:25:58.930+0000] {logging_mixin.py:190} WARNING - /home/airflow/.local/lib/python3.12/site-packages/airflow/utils/log/secrets_masker.py:84 DeprecationWarning: The sensitive_variable_fields option in [admin] has been moved to the sensitive_var_conn_names option in [core] - the old setting has been used, but please update your config.
[2025-02-13T08:25:58.967+0000] {taskinstance.py:3134} INFO - Exporting env vars: AIRFLOW_CTX_DAG_OWNER='airflow' AIRFLOW_CTX_DAG_ID='transform_data_dag' AIRFLOW_CTX_TASK_ID='dbt_test' AIRFLOW_CTX_EXECUTION_DATE='2025-02-13T08:25:56.917849+00:00' AIRFLOW_CTX_TRY_NUMBER='1' AIRFLOW_CTX_DAG_RUN_ID='manual__2025-02-13T08:25:56.917849+00:00'
[2025-02-13T08:25:58.968+0000] {taskinstance.py:732} INFO - ::endgroup::
[2025-02-13T08:25:58.989+0000] {subprocess.py:78} INFO - Tmp dir root location: /tmp
[2025-02-13T08:25:58.991+0000] {subprocess.py:88} INFO - Running command: ['/usr/bin/bash', '-c', 'cd /opt/airflow/dags/dbt/***_project && dbt test']
[2025-02-13T08:25:58.999+0000] {subprocess.py:99} INFO - Output:
[2025-02-13T08:26:01.548+0000] {subprocess.py:106} INFO - [0m08:26:01  Running with dbt=1.8.7
[2025-02-13T08:26:01.873+0000] {subprocess.py:106} INFO - [0m08:26:01  Registered adapter: ***=1.9.0
[2025-02-13T08:26:02.603+0000] {subprocess.py:106} INFO - [0m08:26:02  Found 6 models, 2 data tests, 3 sources, 429 macros
[2025-02-13T08:26:02.607+0000] {subprocess.py:106} INFO - [0m08:26:02
[2025-02-13T08:26:02.713+0000] {subprocess.py:106} INFO - [0m08:26:02  Concurrency: 1 threads (target='dev')
[2025-02-13T08:26:02.714+0000] {subprocess.py:106} INFO - [0m08:26:02
[2025-02-13T08:26:02.726+0000] {subprocess.py:106} INFO - [0m08:26:02  1 of 2 START test not_null_sources_products_product_id ......................... [RUN]
[2025-02-13T08:26:02.834+0000] {subprocess.py:106} INFO - [0m08:26:02  1 of 2 PASS not_null_sources_products_product_id ............................... [[32mPASS[0m in 0.11s]
[2025-02-13T08:26:02.838+0000] {subprocess.py:106} INFO - [0m08:26:02  2 of 2 START test unique_sources_products_product_id ........................... [RUN]
[2025-02-13T08:26:02.899+0000] {subprocess.py:106} INFO - [0m08:26:02  2 of 2 FAIL 2 unique_sources_products_product_id ............................... [[31mFAIL 2[0m in 0.06s]
[2025-02-13T08:26:02.917+0000] {subprocess.py:106} INFO - [0m08:26:02
[2025-02-13T08:26:02.918+0000] {subprocess.py:106} INFO - [0m08:26:02  Finished running 2 data tests in 0 hours 0 minutes and 0.31 seconds (0.31s).
[2025-02-13T08:26:02.993+0000] {subprocess.py:106} INFO - [0m08:26:02
[2025-02-13T08:26:02.995+0000] {subprocess.py:106} INFO - [0m08:26:02  [31mCompleted with 1 error and 0 warnings:[0m
[2025-02-13T08:26:02.996+0000] {subprocess.py:106} INFO - [0m08:26:02
[2025-02-13T08:26:02.997+0000] {subprocess.py:106} INFO - [0m08:26:02  [31mFailure in test unique_sources_products_product_id (models/schema.yml)[0m
[2025-02-13T08:26:02.998+0000] {subprocess.py:106} INFO - [0m08:26:02    Got 2 results, configured to fail if != 0
[2025-02-13T08:26:02.999+0000] {subprocess.py:106} INFO - [0m08:26:02
[2025-02-13T08:26:03.000+0000] {subprocess.py:106} INFO - [0m08:26:02    compiled code at target/compiled/***_project/models/schema.yml/unique_sources_products_product_id.sql
[2025-02-13T08:26:03.000+0000] {subprocess.py:106} INFO - [0m08:26:03
[2025-02-13T08:26:03.002+0000] {subprocess.py:106} INFO - [0m08:26:03  Done. PASS=1 WARN=0 ERROR=1 SKIP=0 TOTAL=2
[2025-02-13T08:26:03.785+0000] {subprocess.py:110} INFO - Command exited with return code 1
[2025-02-13T08:26:03.802+0000] {taskinstance.py:3313} ERROR - Task failed with exception
Traceback (most recent call last):
  File "/home/airflow/.local/lib/python3.12/site-packages/airflow/models/taskinstance.py", line 768, in _execute_task
    result = _execute_callable(context=context, **execute_callable_kwargs)
             ^^^^^^^^^^^^^^^^^^^^^^^^^^^^^^^^^^^^^^^^^^^^^^^^^^^^^^^^^^^^^
  File "/home/airflow/.local/lib/python3.12/site-packages/airflow/models/taskinstance.py", line 734, in _execute_callable
    return ExecutionCallableRunner(
           ^^^^^^^^^^^^^^^^^^^^^^^^
  File "/home/airflow/.local/lib/python3.12/site-packages/airflow/utils/operator_helpers.py", line 252, in run
    return self.func(*args, **kwargs)
           ^^^^^^^^^^^^^^^^^^^^^^^^^^
  File "/home/airflow/.local/lib/python3.12/site-packages/airflow/models/baseoperator.py", line 424, in wrapper
    return func(self, *args, **kwargs)
           ^^^^^^^^^^^^^^^^^^^^^^^^^^^
  File "/home/airflow/.local/lib/python3.12/site-packages/airflow/operators/bash.py", line 276, in execute
    raise AirflowException(
airflow.exceptions.AirflowException: Bash command failed. The command returned a non-zero exit code 1.
[2025-02-13T08:26:03.811+0000] {taskinstance.py:1226} INFO - Marking task as FAILED. dag_id=transform_data_dag, task_id=dbt_test, run_id=manual__2025-02-13T08:25:56.917849+00:00, execution_date=20250213T082556, start_date=20250213T082558, end_date=20250213T082603
[2025-02-13T08:26:03.848+0000] {taskinstance.py:341} INFO - ::group::Post task execution logs
[2025-02-13T08:26:03.848+0000] {standard_task_runner.py:124} ERROR - Failed to execute job 74 for task dbt_test (Bash command failed. The command returned a non-zero exit code 1.; 6048)
Traceback (most recent call last):
  File "/home/airflow/.local/lib/python3.12/site-packages/airflow/task/task_runner/standard_task_runner.py", line 117, in _start_by_fork
    ret = args.func(args, dag=self.dag)
          ^^^^^^^^^^^^^^^^^^^^^^^^^^^^^
  File "/home/airflow/.local/lib/python3.12/site-packages/airflow/cli/cli_config.py", line 49, in command
    return func(*args, **kwargs)
           ^^^^^^^^^^^^^^^^^^^^^
  File "/home/airflow/.local/lib/python3.12/site-packages/airflow/utils/cli.py", line 116, in wrapper
    return f(*args, **kwargs)
           ^^^^^^^^^^^^^^^^^^
  File "/home/airflow/.local/lib/python3.12/site-packages/airflow/cli/commands/task_command.py", line 483, in task_run
    task_return_code = _run_task_by_selected_method(args, _dag, ti)
                       ^^^^^^^^^^^^^^^^^^^^^^^^^^^^^^^^^^^^^^^^^^^^
  File "/home/airflow/.local/lib/python3.12/site-packages/airflow/cli/commands/task_command.py", line 256, in _run_task_by_selected_method
    return _run_raw_task(args, ti)
           ^^^^^^^^^^^^^^^^^^^^^^^
  File "/home/airflow/.local/lib/python3.12/site-packages/airflow/cli/commands/task_command.py", line 341, in _run_raw_task
    return ti._run_raw_task(
           ^^^^^^^^^^^^^^^^^
  File "/home/airflow/.local/lib/python3.12/site-packages/airflow/utils/session.py", line 97, in wrapper
    return func(*args, session=session, **kwargs)
           ^^^^^^^^^^^^^^^^^^^^^^^^^^^^^^^^^^^^^^
  File "/home/airflow/.local/lib/python3.12/site-packages/airflow/models/taskinstance.py", line 3006, in _run_raw_task
    return _run_raw_task(
           ^^^^^^^^^^^^^^
  File "/home/airflow/.local/lib/python3.12/site-packages/airflow/models/taskinstance.py", line 274, in _run_raw_task
    TaskInstance._execute_task_with_callbacks(
  File "/home/airflow/.local/lib/python3.12/site-packages/airflow/models/taskinstance.py", line 3161, in _execute_task_with_callbacks
    result = self._execute_task(context, task_orig)
             ^^^^^^^^^^^^^^^^^^^^^^^^^^^^^^^^^^^^^^
  File "/home/airflow/.local/lib/python3.12/site-packages/airflow/models/taskinstance.py", line 3185, in _execute_task
    return _execute_task(self, context, task_orig)
           ^^^^^^^^^^^^^^^^^^^^^^^^^^^^^^^^^^^^^^^
  File "/home/airflow/.local/lib/python3.12/site-packages/airflow/models/taskinstance.py", line 768, in _execute_task
    result = _execute_callable(context=context, **execute_callable_kwargs)
             ^^^^^^^^^^^^^^^^^^^^^^^^^^^^^^^^^^^^^^^^^^^^^^^^^^^^^^^^^^^^^
  File "/home/airflow/.local/lib/python3.12/site-packages/airflow/models/taskinstance.py", line 734, in _execute_callable
    return ExecutionCallableRunner(
           ^^^^^^^^^^^^^^^^^^^^^^^^
  File "/home/airflow/.local/lib/python3.12/site-packages/airflow/utils/operator_helpers.py", line 252, in run
    return self.func(*args, **kwargs)
           ^^^^^^^^^^^^^^^^^^^^^^^^^^
  File "/home/airflow/.local/lib/python3.12/site-packages/airflow/models/baseoperator.py", line 424, in wrapper
    return func(self, *args, **kwargs)
           ^^^^^^^^^^^^^^^^^^^^^^^^^^^
  File "/home/airflow/.local/lib/python3.12/site-packages/airflow/operators/bash.py", line 276, in execute
    raise AirflowException(
airflow.exceptions.AirflowException: Bash command failed. The command returned a non-zero exit code 1.
[2025-02-13T08:26:03.878+0000] {local_task_job_runner.py:266} INFO - Task exited with return code 1
[2025-02-13T08:26:03.903+0000] {taskinstance.py:3901} INFO - 1 downstream tasks scheduled from follow-on schedule check
[2025-02-13T08:26:03.905+0000] {local_task_job_runner.py:245} INFO - ::endgroup::
