[2025-02-13T04:24:34.608+0000] {local_task_job_runner.py:123} INFO - ::group::Pre task execution logs
[2025-02-13T04:24:34.633+0000] {taskinstance.py:2614} INFO - Dependencies all met for dep_context=non-requeueable deps ti=<TaskInstance: transform_data_dag.dbt_run manual__2025-02-13T04:24:33.106176+00:00 [queued]>
[2025-02-13T04:24:34.644+0000] {taskinstance.py:2614} INFO - Dependencies all met for dep_context=requeueable deps ti=<TaskInstance: transform_data_dag.dbt_run manual__2025-02-13T04:24:33.106176+00:00 [queued]>
[2025-02-13T04:24:34.645+0000] {taskinstance.py:2867} INFO - Starting attempt 1 of 1
[2025-02-13T04:24:34.660+0000] {taskinstance.py:2890} INFO - Executing <Task(BashOperator): dbt_run> on 2025-02-13 04:24:33.106176+00:00
[2025-02-13T04:24:34.669+0000] {logging_mixin.py:190} WARNING - /home/airflow/.local/lib/python3.12/site-packages/airflow/task/task_runner/standard_task_runner.py:70 DeprecationWarning: This process (pid=274) is multi-threaded, use of fork() may lead to deadlocks in the child.
[2025-02-13T04:24:34.669+0000] {standard_task_runner.py:104} INFO - Running: ['airflow', 'tasks', 'run', 'transform_data_dag', 'dbt_run', 'manual__2025-02-13T04:24:33.106176+00:00', '--job-id', '11', '--raw', '--subdir', 'DAGS_FOLDER/transform_data_dag.py', '--cfg-path', '/tmp/tmpmk3_aeft']
[2025-02-13T04:24:34.671+0000] {standard_task_runner.py:72} INFO - Started process 275 to run task
[2025-02-13T04:24:34.671+0000] {standard_task_runner.py:105} INFO - Job 11: Subtask dbt_run
[2025-02-13T04:24:34.690+0000] {logging_mixin.py:190} WARNING - /home/airflow/.local/lib/python3.12/site-packages/airflow/settings.py:209 DeprecationWarning: The sql_alchemy_conn option in [core] has been moved to the sql_alchemy_conn option in [database] - the old setting has been used, but please update your config.
[2025-02-13T04:24:34.726+0000] {task_command.py:467} INFO - Running <TaskInstance: transform_data_dag.dbt_run manual__2025-02-13T04:24:33.106176+00:00 [running]> on host 89bb8c6379b5
[2025-02-13T04:24:34.783+0000] {logging_mixin.py:190} WARNING - /home/airflow/.local/lib/python3.12/site-packages/airflow/utils/log/secrets_masker.py:84 DeprecationWarning: The sensitive_variable_fields option in [admin] has been moved to the sensitive_var_conn_names option in [core] - the old setting has been used, but please update your config.
[2025-02-13T04:24:34.815+0000] {taskinstance.py:3134} INFO - Exporting env vars: AIRFLOW_CTX_DAG_OWNER='airflow' AIRFLOW_CTX_DAG_ID='transform_data_dag' AIRFLOW_CTX_TASK_ID='dbt_run' AIRFLOW_CTX_EXECUTION_DATE='2025-02-13T04:24:33.106176+00:00' AIRFLOW_CTX_TRY_NUMBER='1' AIRFLOW_CTX_DAG_RUN_ID='manual__2025-02-13T04:24:33.106176+00:00'
[2025-02-13T04:24:34.816+0000] {taskinstance.py:732} INFO - ::endgroup::
[2025-02-13T04:24:34.834+0000] {subprocess.py:78} INFO - Tmp dir root location: /tmp
[2025-02-13T04:24:34.836+0000] {subprocess.py:88} INFO - Running command: ['/usr/bin/bash', '-c', 'cd /opt/airflow/dags/dbt/***_project && dbt run']
[2025-02-13T04:24:34.843+0000] {subprocess.py:99} INFO - Output:
[2025-02-13T04:24:37.774+0000] {subprocess.py:106} INFO - [0m04:24:37  Running with dbt=1.8.7
[2025-02-13T04:24:38.129+0000] {subprocess.py:106} INFO - [0m04:24:38  Registered adapter: ***=1.9.0
[2025-02-13T04:24:38.423+0000] {subprocess.py:106} INFO - [0m04:24:38  Unable to do partial parsing because a project config has changed
[2025-02-13T04:24:40.268+0000] {subprocess.py:106} INFO - [0m04:24:40  Found 3 models, 429 macros
[2025-02-13T04:24:40.271+0000] {subprocess.py:106} INFO - [0m04:24:40
[2025-02-13T04:24:40.413+0000] {subprocess.py:106} INFO - [0m04:24:40  Concurrency: 1 threads (target='dev')
[2025-02-13T04:24:40.414+0000] {subprocess.py:106} INFO - [0m04:24:40
[2025-02-13T04:24:40.427+0000] {subprocess.py:106} INFO - [0m04:24:40  1 of 3 START sql view model raw.sources_order_items ............................ [RUN]
[2025-02-13T04:24:40.594+0000] {subprocess.py:106} INFO - [0m04:24:40  1 of 3 OK created sql view model raw.sources_order_items ....................... [[32mCREATE VIEW[0m in 0.16s]
[2025-02-13T04:24:40.597+0000] {subprocess.py:106} INFO - [0m04:24:40  2 of 3 START sql view model raw.sources_orders ................................. [RUN]
[2025-02-13T04:24:40.760+0000] {subprocess.py:106} INFO - [0m04:24:40  2 of 3 ERROR creating sql view model raw.sources_orders ........................ [[31mERROR[0m in 0.16s]
[2025-02-13T04:24:40.764+0000] {subprocess.py:106} INFO - [0m04:24:40  3 of 3 START sql view model raw.sources_products ............................... [RUN]
[2025-02-13T04:24:40.840+0000] {subprocess.py:106} INFO - [0m04:24:40  3 of 3 ERROR creating sql view model raw.sources_products ...................... [[31mERROR[0m in 0.07s]
[2025-02-13T04:24:40.863+0000] {subprocess.py:106} INFO - [0m04:24:40
[2025-02-13T04:24:40.864+0000] {subprocess.py:106} INFO - [0m04:24:40  Finished running 3 view models in 0 hours 0 minutes and 0.59 seconds (0.59s).
[2025-02-13T04:24:40.942+0000] {subprocess.py:106} INFO - [0m04:24:40
[2025-02-13T04:24:40.944+0000] {subprocess.py:106} INFO - [0m04:24:40  [31mCompleted with 2 errors and 0 warnings:[0m
[2025-02-13T04:24:40.945+0000] {subprocess.py:106} INFO - [0m04:24:40
[2025-02-13T04:24:40.947+0000] {subprocess.py:106} INFO - [0m04:24:40    Database Error in model sources_orders (models/sources/sources_orders.sql)
[2025-02-13T04:24:40.948+0000] {subprocess.py:106} INFO -   relation "sources_orders" already exists
[2025-02-13T04:24:40.948+0000] {subprocess.py:106} INFO -   compiled code at target/run/***_project/models/sources/sources_orders.sql
[2025-02-13T04:24:40.949+0000] {subprocess.py:106} INFO - [0m04:24:40
[2025-02-13T04:24:40.949+0000] {subprocess.py:106} INFO - [0m04:24:40    Database Error in model sources_products (models/sources/sources_products.sql)
[2025-02-13T04:24:40.950+0000] {subprocess.py:106} INFO -   relation "sources_products" already exists
[2025-02-13T04:24:40.950+0000] {subprocess.py:106} INFO -   compiled code at target/run/***_project/models/sources/sources_products.sql
[2025-02-13T04:24:40.951+0000] {subprocess.py:106} INFO - [0m04:24:40
[2025-02-13T04:24:40.951+0000] {subprocess.py:106} INFO - [0m04:24:40  Done. PASS=1 WARN=0 ERROR=2 SKIP=0 TOTAL=3
[2025-02-13T04:24:41.755+0000] {subprocess.py:110} INFO - Command exited with return code 1
[2025-02-13T04:24:41.773+0000] {taskinstance.py:3313} ERROR - Task failed with exception
Traceback (most recent call last):
  File "/home/airflow/.local/lib/python3.12/site-packages/airflow/models/taskinstance.py", line 768, in _execute_task
    result = _execute_callable(context=context, **execute_callable_kwargs)
             ^^^^^^^^^^^^^^^^^^^^^^^^^^^^^^^^^^^^^^^^^^^^^^^^^^^^^^^^^^^^^
  File "/home/airflow/.local/lib/python3.12/site-packages/airflow/models/taskinstance.py", line 734, in _execute_callable
    return ExecutionCallableRunner(
           ^^^^^^^^^^^^^^^^^^^^^^^^
  File "/home/airflow/.local/lib/python3.12/site-packages/airflow/utils/operator_helpers.py", line 252, in run
    return self.func(*args, **kwargs)
           ^^^^^^^^^^^^^^^^^^^^^^^^^^
  File "/home/airflow/.local/lib/python3.12/site-packages/airflow/models/baseoperator.py", line 424, in wrapper
    return func(self, *args, **kwargs)
           ^^^^^^^^^^^^^^^^^^^^^^^^^^^
  File "/home/airflow/.local/lib/python3.12/site-packages/airflow/operators/bash.py", line 276, in execute
    raise AirflowException(
airflow.exceptions.AirflowException: Bash command failed. The command returned a non-zero exit code 1.
[2025-02-13T04:24:41.778+0000] {taskinstance.py:1226} INFO - Marking task as FAILED. dag_id=transform_data_dag, task_id=dbt_run, run_id=manual__2025-02-13T04:24:33.106176+00:00, execution_date=20250213T042433, start_date=20250213T042434, end_date=20250213T042441
[2025-02-13T04:24:41.808+0000] {taskinstance.py:341} INFO - ::group::Post task execution logs
[2025-02-13T04:24:41.808+0000] {standard_task_runner.py:124} ERROR - Failed to execute job 11 for task dbt_run (Bash command failed. The command returned a non-zero exit code 1.; 275)
Traceback (most recent call last):
  File "/home/airflow/.local/lib/python3.12/site-packages/airflow/task/task_runner/standard_task_runner.py", line 117, in _start_by_fork
    ret = args.func(args, dag=self.dag)
          ^^^^^^^^^^^^^^^^^^^^^^^^^^^^^
  File "/home/airflow/.local/lib/python3.12/site-packages/airflow/cli/cli_config.py", line 49, in command
    return func(*args, **kwargs)
           ^^^^^^^^^^^^^^^^^^^^^
  File "/home/airflow/.local/lib/python3.12/site-packages/airflow/utils/cli.py", line 116, in wrapper
    return f(*args, **kwargs)
           ^^^^^^^^^^^^^^^^^^
  File "/home/airflow/.local/lib/python3.12/site-packages/airflow/cli/commands/task_command.py", line 483, in task_run
    task_return_code = _run_task_by_selected_method(args, _dag, ti)
                       ^^^^^^^^^^^^^^^^^^^^^^^^^^^^^^^^^^^^^^^^^^^^
  File "/home/airflow/.local/lib/python3.12/site-packages/airflow/cli/commands/task_command.py", line 256, in _run_task_by_selected_method
    return _run_raw_task(args, ti)
           ^^^^^^^^^^^^^^^^^^^^^^^
  File "/home/airflow/.local/lib/python3.12/site-packages/airflow/cli/commands/task_command.py", line 341, in _run_raw_task
    return ti._run_raw_task(
           ^^^^^^^^^^^^^^^^^
  File "/home/airflow/.local/lib/python3.12/site-packages/airflow/utils/session.py", line 97, in wrapper
    return func(*args, session=session, **kwargs)
           ^^^^^^^^^^^^^^^^^^^^^^^^^^^^^^^^^^^^^^
  File "/home/airflow/.local/lib/python3.12/site-packages/airflow/models/taskinstance.py", line 3006, in _run_raw_task
    return _run_raw_task(
           ^^^^^^^^^^^^^^
  File "/home/airflow/.local/lib/python3.12/site-packages/airflow/models/taskinstance.py", line 274, in _run_raw_task
    TaskInstance._execute_task_with_callbacks(
  File "/home/airflow/.local/lib/python3.12/site-packages/airflow/models/taskinstance.py", line 3161, in _execute_task_with_callbacks
    result = self._execute_task(context, task_orig)
             ^^^^^^^^^^^^^^^^^^^^^^^^^^^^^^^^^^^^^^
  File "/home/airflow/.local/lib/python3.12/site-packages/airflow/models/taskinstance.py", line 3185, in _execute_task
    return _execute_task(self, context, task_orig)
           ^^^^^^^^^^^^^^^^^^^^^^^^^^^^^^^^^^^^^^^
  File "/home/airflow/.local/lib/python3.12/site-packages/airflow/models/taskinstance.py", line 768, in _execute_task
    result = _execute_callable(context=context, **execute_callable_kwargs)
             ^^^^^^^^^^^^^^^^^^^^^^^^^^^^^^^^^^^^^^^^^^^^^^^^^^^^^^^^^^^^^
  File "/home/airflow/.local/lib/python3.12/site-packages/airflow/models/taskinstance.py", line 734, in _execute_callable
    return ExecutionCallableRunner(
           ^^^^^^^^^^^^^^^^^^^^^^^^
  File "/home/airflow/.local/lib/python3.12/site-packages/airflow/utils/operator_helpers.py", line 252, in run
    return self.func(*args, **kwargs)
           ^^^^^^^^^^^^^^^^^^^^^^^^^^
  File "/home/airflow/.local/lib/python3.12/site-packages/airflow/models/baseoperator.py", line 424, in wrapper
    return func(self, *args, **kwargs)
           ^^^^^^^^^^^^^^^^^^^^^^^^^^^
  File "/home/airflow/.local/lib/python3.12/site-packages/airflow/operators/bash.py", line 276, in execute
    raise AirflowException(
airflow.exceptions.AirflowException: Bash command failed. The command returned a non-zero exit code 1.
[2025-02-13T04:24:41.840+0000] {local_task_job_runner.py:266} INFO - Task exited with return code 1
[2025-02-13T04:24:41.889+0000] {taskinstance.py:3901} INFO - 0 downstream tasks scheduled from follow-on schedule check
[2025-02-13T04:24:41.894+0000] {local_task_job_runner.py:245} INFO - ::endgroup::
