[2025-02-13T08:41:56.776+0000] {local_task_job_runner.py:123} INFO - ::group::Pre task execution logs
[2025-02-13T08:41:56.804+0000] {taskinstance.py:2614} INFO - Dependencies all met for dep_context=non-requeueable deps ti=<TaskInstance: transform_data_dag.dbt_test manual__2025-02-13T08:41:55.173686+00:00 [queued]>
[2025-02-13T08:41:56.829+0000] {taskinstance.py:2614} INFO - Dependencies all met for dep_context=requeueable deps ti=<TaskInstance: transform_data_dag.dbt_test manual__2025-02-13T08:41:55.173686+00:00 [queued]>
[2025-02-13T08:41:56.830+0000] {taskinstance.py:2867} INFO - Starting attempt 1 of 1
[2025-02-13T08:41:56.860+0000] {taskinstance.py:2890} INFO - Executing <Task(BashOperator): dbt_test> on 2025-02-13 08:41:55.173686+00:00
[2025-02-13T08:41:56.869+0000] {standard_task_runner.py:104} INFO - Running: ['airflow', 'tasks', 'run', 'transform_data_dag', 'dbt_test', 'manual__2025-02-13T08:41:55.173686+00:00', '--job-id', '76', '--raw', '--subdir', 'DAGS_FOLDER/transform_data_dag.py', '--cfg-path', '/tmp/tmpah3ro81l']
[2025-02-13T08:41:56.872+0000] {logging_mixin.py:190} WARNING - /home/airflow/.local/lib/python3.12/site-packages/airflow/task/task_runner/standard_task_runner.py:70 DeprecationWarning: This process (pid=6416) is multi-threaded, use of fork() may lead to deadlocks in the child.
[2025-02-13T08:41:56.876+0000] {standard_task_runner.py:105} INFO - Job 76: Subtask dbt_test
[2025-02-13T08:41:56.876+0000] {standard_task_runner.py:72} INFO - Started process 6417 to run task
[2025-02-13T08:41:56.907+0000] {logging_mixin.py:190} WARNING - /home/airflow/.local/lib/python3.12/site-packages/airflow/settings.py:209 DeprecationWarning: The sql_alchemy_conn option in [core] has been moved to the sql_alchemy_conn option in [database] - the old setting has been used, but please update your config.
[2025-02-13T08:41:56.961+0000] {task_command.py:467} INFO - Running <TaskInstance: transform_data_dag.dbt_test manual__2025-02-13T08:41:55.173686+00:00 [running]> on host 89bb8c6379b5
[2025-02-13T08:41:57.032+0000] {logging_mixin.py:190} WARNING - /home/airflow/.local/lib/python3.12/site-packages/airflow/utils/log/secrets_masker.py:84 DeprecationWarning: The sensitive_variable_fields option in [admin] has been moved to the sensitive_var_conn_names option in [core] - the old setting has been used, but please update your config.
[2025-02-13T08:41:57.068+0000] {taskinstance.py:3134} INFO - Exporting env vars: AIRFLOW_CTX_DAG_OWNER='airflow' AIRFLOW_CTX_DAG_ID='transform_data_dag' AIRFLOW_CTX_TASK_ID='dbt_test' AIRFLOW_CTX_EXECUTION_DATE='2025-02-13T08:41:55.173686+00:00' AIRFLOW_CTX_TRY_NUMBER='1' AIRFLOW_CTX_DAG_RUN_ID='manual__2025-02-13T08:41:55.173686+00:00'
[2025-02-13T08:41:57.069+0000] {taskinstance.py:732} INFO - ::endgroup::
[2025-02-13T08:41:57.094+0000] {subprocess.py:78} INFO - Tmp dir root location: /tmp
[2025-02-13T08:41:57.097+0000] {subprocess.py:88} INFO - Running command: ['/usr/bin/bash', '-c', 'cd /opt/airflow/dags/dbt/***_project && dbt test']
[2025-02-13T08:41:57.104+0000] {subprocess.py:99} INFO - Output:
[2025-02-13T08:41:59.471+0000] {subprocess.py:106} INFO - [0m08:41:59  Running with dbt=1.8.7
[2025-02-13T08:41:59.786+0000] {subprocess.py:106} INFO - [0m08:41:59  Registered adapter: ***=1.9.0
[2025-02-13T08:42:00.840+0000] {subprocess.py:106} INFO - [0m08:42:00  Found 6 models, 2 data tests, 3 sources, 429 macros
[2025-02-13T08:42:00.844+0000] {subprocess.py:106} INFO - [0m08:42:00
[2025-02-13T08:42:00.954+0000] {subprocess.py:106} INFO - [0m08:42:00  Concurrency: 1 threads (target='dev')
[2025-02-13T08:42:00.955+0000] {subprocess.py:106} INFO - [0m08:42:00
[2025-02-13T08:42:00.967+0000] {subprocess.py:106} INFO - [0m08:42:00  1 of 2 START test not_null_sources_products_product_id ......................... [RUN]
[2025-02-13T08:42:01.074+0000] {subprocess.py:106} INFO - [0m08:42:01  1 of 2 PASS not_null_sources_products_product_id ............................... [[32mPASS[0m in 0.11s]
[2025-02-13T08:42:01.078+0000] {subprocess.py:106} INFO - [0m08:42:01  2 of 2 START test unique_sources_products_product_id ........................... [RUN]
[2025-02-13T08:42:01.131+0000] {subprocess.py:106} INFO - [0m08:42:01  2 of 2 FAIL 2 unique_sources_products_product_id ............................... [[31mFAIL 2[0m in 0.05s]
[2025-02-13T08:42:01.150+0000] {subprocess.py:106} INFO - [0m08:42:01
[2025-02-13T08:42:01.151+0000] {subprocess.py:106} INFO - [0m08:42:01  Finished running 2 data tests in 0 hours 0 minutes and 0.30 seconds (0.30s).
[2025-02-13T08:42:01.228+0000] {subprocess.py:106} INFO - [0m08:42:01
[2025-02-13T08:42:01.229+0000] {subprocess.py:106} INFO - [0m08:42:01  [31mCompleted with 1 error and 0 warnings:[0m
[2025-02-13T08:42:01.230+0000] {subprocess.py:106} INFO - [0m08:42:01
[2025-02-13T08:42:01.231+0000] {subprocess.py:106} INFO - [0m08:42:01  [31mFailure in test unique_sources_products_product_id (models/schema.yml)[0m
[2025-02-13T08:42:01.232+0000] {subprocess.py:106} INFO - [0m08:42:01    Got 2 results, configured to fail if != 0
[2025-02-13T08:42:01.232+0000] {subprocess.py:106} INFO - [0m08:42:01
[2025-02-13T08:42:01.233+0000] {subprocess.py:106} INFO - [0m08:42:01    compiled code at target/compiled/***_project/models/schema.yml/unique_sources_products_product_id.sql
[2025-02-13T08:42:01.234+0000] {subprocess.py:106} INFO - [0m08:42:01
[2025-02-13T08:42:01.235+0000] {subprocess.py:106} INFO - [0m08:42:01  Done. PASS=1 WARN=0 ERROR=1 SKIP=0 TOTAL=2
[2025-02-13T08:42:01.975+0000] {subprocess.py:110} INFO - Command exited with return code 1
[2025-02-13T08:42:01.986+0000] {taskinstance.py:3313} ERROR - Task failed with exception
Traceback (most recent call last):
  File "/home/airflow/.local/lib/python3.12/site-packages/airflow/models/taskinstance.py", line 768, in _execute_task
    result = _execute_callable(context=context, **execute_callable_kwargs)
             ^^^^^^^^^^^^^^^^^^^^^^^^^^^^^^^^^^^^^^^^^^^^^^^^^^^^^^^^^^^^^
  File "/home/airflow/.local/lib/python3.12/site-packages/airflow/models/taskinstance.py", line 734, in _execute_callable
    return ExecutionCallableRunner(
           ^^^^^^^^^^^^^^^^^^^^^^^^
  File "/home/airflow/.local/lib/python3.12/site-packages/airflow/utils/operator_helpers.py", line 252, in run
    return self.func(*args, **kwargs)
           ^^^^^^^^^^^^^^^^^^^^^^^^^^
  File "/home/airflow/.local/lib/python3.12/site-packages/airflow/models/baseoperator.py", line 424, in wrapper
    return func(self, *args, **kwargs)
           ^^^^^^^^^^^^^^^^^^^^^^^^^^^
  File "/home/airflow/.local/lib/python3.12/site-packages/airflow/operators/bash.py", line 276, in execute
    raise AirflowException(
airflow.exceptions.AirflowException: Bash command failed. The command returned a non-zero exit code 1.
[2025-02-13T08:42:01.992+0000] {taskinstance.py:1226} INFO - Marking task as FAILED. dag_id=transform_data_dag, task_id=dbt_test, run_id=manual__2025-02-13T08:41:55.173686+00:00, execution_date=20250213T084155, start_date=20250213T084156, end_date=20250213T084201
[2025-02-13T08:42:02.021+0000] {taskinstance.py:341} INFO - ::group::Post task execution logs
[2025-02-13T08:42:02.022+0000] {standard_task_runner.py:124} ERROR - Failed to execute job 76 for task dbt_test (Bash command failed. The command returned a non-zero exit code 1.; 6417)
Traceback (most recent call last):
  File "/home/airflow/.local/lib/python3.12/site-packages/airflow/task/task_runner/standard_task_runner.py", line 117, in _start_by_fork
    ret = args.func(args, dag=self.dag)
          ^^^^^^^^^^^^^^^^^^^^^^^^^^^^^
  File "/home/airflow/.local/lib/python3.12/site-packages/airflow/cli/cli_config.py", line 49, in command
    return func(*args, **kwargs)
           ^^^^^^^^^^^^^^^^^^^^^
  File "/home/airflow/.local/lib/python3.12/site-packages/airflow/utils/cli.py", line 116, in wrapper
    return f(*args, **kwargs)
           ^^^^^^^^^^^^^^^^^^
  File "/home/airflow/.local/lib/python3.12/site-packages/airflow/cli/commands/task_command.py", line 483, in task_run
    task_return_code = _run_task_by_selected_method(args, _dag, ti)
                       ^^^^^^^^^^^^^^^^^^^^^^^^^^^^^^^^^^^^^^^^^^^^
  File "/home/airflow/.local/lib/python3.12/site-packages/airflow/cli/commands/task_command.py", line 256, in _run_task_by_selected_method
    return _run_raw_task(args, ti)
           ^^^^^^^^^^^^^^^^^^^^^^^
  File "/home/airflow/.local/lib/python3.12/site-packages/airflow/cli/commands/task_command.py", line 341, in _run_raw_task
    return ti._run_raw_task(
           ^^^^^^^^^^^^^^^^^
  File "/home/airflow/.local/lib/python3.12/site-packages/airflow/utils/session.py", line 97, in wrapper
    return func(*args, session=session, **kwargs)
           ^^^^^^^^^^^^^^^^^^^^^^^^^^^^^^^^^^^^^^
  File "/home/airflow/.local/lib/python3.12/site-packages/airflow/models/taskinstance.py", line 3006, in _run_raw_task
    return _run_raw_task(
           ^^^^^^^^^^^^^^
  File "/home/airflow/.local/lib/python3.12/site-packages/airflow/models/taskinstance.py", line 274, in _run_raw_task
    TaskInstance._execute_task_with_callbacks(
  File "/home/airflow/.local/lib/python3.12/site-packages/airflow/models/taskinstance.py", line 3161, in _execute_task_with_callbacks
    result = self._execute_task(context, task_orig)
             ^^^^^^^^^^^^^^^^^^^^^^^^^^^^^^^^^^^^^^
  File "/home/airflow/.local/lib/python3.12/site-packages/airflow/models/taskinstance.py", line 3185, in _execute_task
    return _execute_task(self, context, task_orig)
           ^^^^^^^^^^^^^^^^^^^^^^^^^^^^^^^^^^^^^^^
  File "/home/airflow/.local/lib/python3.12/site-packages/airflow/models/taskinstance.py", line 768, in _execute_task
    result = _execute_callable(context=context, **execute_callable_kwargs)
             ^^^^^^^^^^^^^^^^^^^^^^^^^^^^^^^^^^^^^^^^^^^^^^^^^^^^^^^^^^^^^
  File "/home/airflow/.local/lib/python3.12/site-packages/airflow/models/taskinstance.py", line 734, in _execute_callable
    return ExecutionCallableRunner(
           ^^^^^^^^^^^^^^^^^^^^^^^^
  File "/home/airflow/.local/lib/python3.12/site-packages/airflow/utils/operator_helpers.py", line 252, in run
    return self.func(*args, **kwargs)
           ^^^^^^^^^^^^^^^^^^^^^^^^^^
  File "/home/airflow/.local/lib/python3.12/site-packages/airflow/models/baseoperator.py", line 424, in wrapper
    return func(self, *args, **kwargs)
           ^^^^^^^^^^^^^^^^^^^^^^^^^^^
  File "/home/airflow/.local/lib/python3.12/site-packages/airflow/operators/bash.py", line 276, in execute
    raise AirflowException(
airflow.exceptions.AirflowException: Bash command failed. The command returned a non-zero exit code 1.
[2025-02-13T08:42:02.041+0000] {local_task_job_runner.py:266} INFO - Task exited with return code 1
[2025-02-13T08:42:02.070+0000] {taskinstance.py:3901} INFO - 1 downstream tasks scheduled from follow-on schedule check
[2025-02-13T08:42:02.073+0000] {local_task_job_runner.py:245} INFO - ::endgroup::
