[2025-02-13T08:16:10.008+0000] {local_task_job_runner.py:123} INFO - ::group::Pre task execution logs
[2025-02-13T08:16:10.031+0000] {taskinstance.py:2614} INFO - Dependencies all met for dep_context=non-requeueable deps ti=<TaskInstance: transform_data_dag.dbt_run manual__2025-02-13T08:16:01.794122+00:00 [queued]>
[2025-02-13T08:16:10.041+0000] {taskinstance.py:2614} INFO - Dependencies all met for dep_context=requeueable deps ti=<TaskInstance: transform_data_dag.dbt_run manual__2025-02-13T08:16:01.794122+00:00 [queued]>
[2025-02-13T08:16:10.042+0000] {taskinstance.py:2867} INFO - Starting attempt 1 of 1
[2025-02-13T08:16:10.057+0000] {taskinstance.py:2890} INFO - Executing <Task(BashOperator): dbt_run> on 2025-02-13 08:16:01.794122+00:00
[2025-02-13T08:16:10.064+0000] {logging_mixin.py:190} WARNING - /home/airflow/.local/lib/python3.12/site-packages/airflow/task/task_runner/standard_task_runner.py:70 DeprecationWarning: This process (pid=5756) is multi-threaded, use of fork() may lead to deadlocks in the child.
[2025-02-13T08:16:10.065+0000] {standard_task_runner.py:72} INFO - Started process 5757 to run task
[2025-02-13T08:16:10.064+0000] {standard_task_runner.py:104} INFO - Running: ['airflow', 'tasks', 'run', 'transform_data_dag', 'dbt_run', 'manual__2025-02-13T08:16:01.794122+00:00', '--job-id', '65', '--raw', '--subdir', 'DAGS_FOLDER/transform_data_dag.py', '--cfg-path', '/tmp/tmpfn3cva8m']
[2025-02-13T08:16:10.066+0000] {standard_task_runner.py:105} INFO - Job 65: Subtask dbt_run
[2025-02-13T08:16:10.084+0000] {logging_mixin.py:190} WARNING - /home/airflow/.local/lib/python3.12/site-packages/airflow/settings.py:209 DeprecationWarning: The sql_alchemy_conn option in [core] has been moved to the sql_alchemy_conn option in [database] - the old setting has been used, but please update your config.
[2025-02-13T08:16:10.118+0000] {task_command.py:467} INFO - Running <TaskInstance: transform_data_dag.dbt_run manual__2025-02-13T08:16:01.794122+00:00 [running]> on host 89bb8c6379b5
[2025-02-13T08:16:10.178+0000] {logging_mixin.py:190} WARNING - /home/airflow/.local/lib/python3.12/site-packages/airflow/utils/log/secrets_masker.py:84 DeprecationWarning: The sensitive_variable_fields option in [admin] has been moved to the sensitive_var_conn_names option in [core] - the old setting has been used, but please update your config.
[2025-02-13T08:16:10.211+0000] {taskinstance.py:3134} INFO - Exporting env vars: AIRFLOW_CTX_DAG_OWNER='airflow' AIRFLOW_CTX_DAG_ID='transform_data_dag' AIRFLOW_CTX_TASK_ID='dbt_run' AIRFLOW_CTX_EXECUTION_DATE='2025-02-13T08:16:01.794122+00:00' AIRFLOW_CTX_TRY_NUMBER='1' AIRFLOW_CTX_DAG_RUN_ID='manual__2025-02-13T08:16:01.794122+00:00'
[2025-02-13T08:16:10.211+0000] {taskinstance.py:732} INFO - ::endgroup::
[2025-02-13T08:16:10.228+0000] {subprocess.py:78} INFO - Tmp dir root location: /tmp
[2025-02-13T08:16:10.229+0000] {subprocess.py:88} INFO - Running command: ['/usr/bin/bash', '-c', 'cd /opt/airflow/dags/dbt/***_project && dbt run']
[2025-02-13T08:16:10.237+0000] {subprocess.py:99} INFO - Output:
[2025-02-13T08:16:12.684+0000] {subprocess.py:106} INFO - [0m08:16:12  Running with dbt=1.8.7
[2025-02-13T08:16:12.999+0000] {subprocess.py:106} INFO - [0m08:16:12  Registered adapter: ***=1.9.0
[2025-02-13T08:16:13.754+0000] {subprocess.py:106} INFO - [0m08:16:13  Found 6 models, 2 data tests, 3 sources, 429 macros
[2025-02-13T08:16:13.758+0000] {subprocess.py:106} INFO - [0m08:16:13
[2025-02-13T08:16:13.885+0000] {subprocess.py:106} INFO - [0m08:16:13  Concurrency: 1 threads (target='dev')
[2025-02-13T08:16:13.885+0000] {subprocess.py:106} INFO - [0m08:16:13
[2025-02-13T08:16:13.964+0000] {subprocess.py:106} INFO - [0m08:16:13  1 of 3 START sql incremental model model.order_items ........................... [RUN]
[2025-02-13T08:16:14.213+0000] {subprocess.py:106} INFO - [0m08:16:14  1 of 3 ERROR creating sql incremental model model.order_items .................. [[31mERROR[0m in 0.25s]
[2025-02-13T08:16:14.217+0000] {subprocess.py:106} INFO - [0m08:16:14  2 of 3 START sql incremental model model.orders ................................ [RUN]
[2025-02-13T08:16:14.330+0000] {subprocess.py:106} INFO - [0m08:16:14  2 of 3 ERROR creating sql incremental model model.orders ....................... [[31mERROR[0m in 0.11s]
[2025-02-13T08:16:14.333+0000] {subprocess.py:106} INFO - [0m08:16:14  3 of 3 START sql incremental model model.products .............................. [RUN]
[2025-02-13T08:16:14.449+0000] {subprocess.py:106} INFO - [0m08:16:14  3 of 3 ERROR creating sql incremental model model.products ..................... [[31mERROR[0m in 0.11s]
[2025-02-13T08:16:14.467+0000] {subprocess.py:106} INFO - [0m08:16:14
[2025-02-13T08:16:14.468+0000] {subprocess.py:106} INFO - [0m08:16:14  Finished running 3 incremental models in 0 hours 0 minutes and 0.71 seconds (0.71s).
[2025-02-13T08:16:14.544+0000] {subprocess.py:106} INFO - [0m08:16:14
[2025-02-13T08:16:14.545+0000] {subprocess.py:106} INFO - [0m08:16:14  [31mCompleted with 3 errors and 0 warnings:[0m
[2025-02-13T08:16:14.546+0000] {subprocess.py:106} INFO - [0m08:16:14
[2025-02-13T08:16:14.547+0000] {subprocess.py:106} INFO - [0m08:16:14    Database Error in model order_items (models/cleansed/order_items.sql)
[2025-02-13T08:16:14.548+0000] {subprocess.py:106} INFO -   multiple primary keys for table "order_items" are not allowed
[2025-02-13T08:16:14.548+0000] {subprocess.py:106} INFO -   compiled code at target/run/***_project/models/cleansed/order_items.sql
[2025-02-13T08:16:14.549+0000] {subprocess.py:106} INFO - [0m08:16:14
[2025-02-13T08:16:14.549+0000] {subprocess.py:106} INFO - [0m08:16:14    Database Error in model orders (models/cleansed/orders.sql)
[2025-02-13T08:16:14.550+0000] {subprocess.py:106} INFO -   multiple primary keys for table "orders" are not allowed
[2025-02-13T08:16:14.550+0000] {subprocess.py:106} INFO -   compiled code at target/run/***_project/models/cleansed/orders.sql
[2025-02-13T08:16:14.551+0000] {subprocess.py:106} INFO - [0m08:16:14
[2025-02-13T08:16:14.551+0000] {subprocess.py:106} INFO - [0m08:16:14    Database Error in model products (models/cleansed/products.sql)
[2025-02-13T08:16:14.552+0000] {subprocess.py:106} INFO -   multiple primary keys for table "products" are not allowed
[2025-02-13T08:16:14.552+0000] {subprocess.py:106} INFO -   compiled code at target/run/***_project/models/cleansed/products.sql
[2025-02-13T08:16:14.552+0000] {subprocess.py:106} INFO - [0m08:16:14
[2025-02-13T08:16:14.553+0000] {subprocess.py:106} INFO - [0m08:16:14  Done. PASS=0 WARN=0 ERROR=3 SKIP=0 TOTAL=3
[2025-02-13T08:16:15.268+0000] {subprocess.py:110} INFO - Command exited with return code 1
[2025-02-13T08:16:15.280+0000] {taskinstance.py:3313} ERROR - Task failed with exception
Traceback (most recent call last):
  File "/home/airflow/.local/lib/python3.12/site-packages/airflow/models/taskinstance.py", line 768, in _execute_task
    result = _execute_callable(context=context, **execute_callable_kwargs)
             ^^^^^^^^^^^^^^^^^^^^^^^^^^^^^^^^^^^^^^^^^^^^^^^^^^^^^^^^^^^^^
  File "/home/airflow/.local/lib/python3.12/site-packages/airflow/models/taskinstance.py", line 734, in _execute_callable
    return ExecutionCallableRunner(
           ^^^^^^^^^^^^^^^^^^^^^^^^
  File "/home/airflow/.local/lib/python3.12/site-packages/airflow/utils/operator_helpers.py", line 252, in run
    return self.func(*args, **kwargs)
           ^^^^^^^^^^^^^^^^^^^^^^^^^^
  File "/home/airflow/.local/lib/python3.12/site-packages/airflow/models/baseoperator.py", line 424, in wrapper
    return func(self, *args, **kwargs)
           ^^^^^^^^^^^^^^^^^^^^^^^^^^^
  File "/home/airflow/.local/lib/python3.12/site-packages/airflow/operators/bash.py", line 276, in execute
    raise AirflowException(
airflow.exceptions.AirflowException: Bash command failed. The command returned a non-zero exit code 1.
[2025-02-13T08:16:15.285+0000] {taskinstance.py:1226} INFO - Marking task as FAILED. dag_id=transform_data_dag, task_id=dbt_run, run_id=manual__2025-02-13T08:16:01.794122+00:00, execution_date=20250213T081601, start_date=20250213T081610, end_date=20250213T081615
[2025-02-13T08:16:15.313+0000] {taskinstance.py:341} INFO - ::group::Post task execution logs
[2025-02-13T08:16:15.314+0000] {standard_task_runner.py:124} ERROR - Failed to execute job 65 for task dbt_run (Bash command failed. The command returned a non-zero exit code 1.; 5757)
Traceback (most recent call last):
  File "/home/airflow/.local/lib/python3.12/site-packages/airflow/task/task_runner/standard_task_runner.py", line 117, in _start_by_fork
    ret = args.func(args, dag=self.dag)
          ^^^^^^^^^^^^^^^^^^^^^^^^^^^^^
  File "/home/airflow/.local/lib/python3.12/site-packages/airflow/cli/cli_config.py", line 49, in command
    return func(*args, **kwargs)
           ^^^^^^^^^^^^^^^^^^^^^
  File "/home/airflow/.local/lib/python3.12/site-packages/airflow/utils/cli.py", line 116, in wrapper
    return f(*args, **kwargs)
           ^^^^^^^^^^^^^^^^^^
  File "/home/airflow/.local/lib/python3.12/site-packages/airflow/cli/commands/task_command.py", line 483, in task_run
    task_return_code = _run_task_by_selected_method(args, _dag, ti)
                       ^^^^^^^^^^^^^^^^^^^^^^^^^^^^^^^^^^^^^^^^^^^^
  File "/home/airflow/.local/lib/python3.12/site-packages/airflow/cli/commands/task_command.py", line 256, in _run_task_by_selected_method
    return _run_raw_task(args, ti)
           ^^^^^^^^^^^^^^^^^^^^^^^
  File "/home/airflow/.local/lib/python3.12/site-packages/airflow/cli/commands/task_command.py", line 341, in _run_raw_task
    return ti._run_raw_task(
           ^^^^^^^^^^^^^^^^^
  File "/home/airflow/.local/lib/python3.12/site-packages/airflow/utils/session.py", line 97, in wrapper
    return func(*args, session=session, **kwargs)
           ^^^^^^^^^^^^^^^^^^^^^^^^^^^^^^^^^^^^^^
  File "/home/airflow/.local/lib/python3.12/site-packages/airflow/models/taskinstance.py", line 3006, in _run_raw_task
    return _run_raw_task(
           ^^^^^^^^^^^^^^
  File "/home/airflow/.local/lib/python3.12/site-packages/airflow/models/taskinstance.py", line 274, in _run_raw_task
    TaskInstance._execute_task_with_callbacks(
  File "/home/airflow/.local/lib/python3.12/site-packages/airflow/models/taskinstance.py", line 3161, in _execute_task_with_callbacks
    result = self._execute_task(context, task_orig)
             ^^^^^^^^^^^^^^^^^^^^^^^^^^^^^^^^^^^^^^
  File "/home/airflow/.local/lib/python3.12/site-packages/airflow/models/taskinstance.py", line 3185, in _execute_task
    return _execute_task(self, context, task_orig)
           ^^^^^^^^^^^^^^^^^^^^^^^^^^^^^^^^^^^^^^^
  File "/home/airflow/.local/lib/python3.12/site-packages/airflow/models/taskinstance.py", line 768, in _execute_task
    result = _execute_callable(context=context, **execute_callable_kwargs)
             ^^^^^^^^^^^^^^^^^^^^^^^^^^^^^^^^^^^^^^^^^^^^^^^^^^^^^^^^^^^^^
  File "/home/airflow/.local/lib/python3.12/site-packages/airflow/models/taskinstance.py", line 734, in _execute_callable
    return ExecutionCallableRunner(
           ^^^^^^^^^^^^^^^^^^^^^^^^
  File "/home/airflow/.local/lib/python3.12/site-packages/airflow/utils/operator_helpers.py", line 252, in run
    return self.func(*args, **kwargs)
           ^^^^^^^^^^^^^^^^^^^^^^^^^^
  File "/home/airflow/.local/lib/python3.12/site-packages/airflow/models/baseoperator.py", line 424, in wrapper
    return func(self, *args, **kwargs)
           ^^^^^^^^^^^^^^^^^^^^^^^^^^^
  File "/home/airflow/.local/lib/python3.12/site-packages/airflow/operators/bash.py", line 276, in execute
    raise AirflowException(
airflow.exceptions.AirflowException: Bash command failed. The command returned a non-zero exit code 1.
[2025-02-13T08:16:15.355+0000] {local_task_job_runner.py:266} INFO - Task exited with return code 1
[2025-02-13T08:16:15.381+0000] {taskinstance.py:3901} INFO - 0 downstream tasks scheduled from follow-on schedule check
[2025-02-13T08:16:15.386+0000] {local_task_job_runner.py:245} INFO - ::endgroup::
