[2025-02-13T04:11:00.318+0000] {local_task_job_runner.py:123} INFO - ::group::Pre task execution logs
[2025-02-13T04:11:00.342+0000] {taskinstance.py:2614} INFO - Dependencies all met for dep_context=non-requeueable deps ti=<TaskInstance: transform_data_dag.dbt_run manual__2025-02-13T04:10:58.490297+00:00 [queued]>
[2025-02-13T04:11:00.355+0000] {taskinstance.py:2614} INFO - Dependencies all met for dep_context=requeueable deps ti=<TaskInstance: transform_data_dag.dbt_run manual__2025-02-13T04:10:58.490297+00:00 [queued]>
[2025-02-13T04:11:00.356+0000] {taskinstance.py:2867} INFO - Starting attempt 1 of 1
[2025-02-13T04:11:00.372+0000] {taskinstance.py:2890} INFO - Executing <Task(BashOperator): dbt_run> on 2025-02-13 04:10:58.490297+00:00
[2025-02-13T04:11:00.380+0000] {logging_mixin.py:190} WARNING - /home/airflow/.local/lib/python3.12/site-packages/airflow/task/task_runner/standard_task_runner.py:70 DeprecationWarning: This process (pid=1388) is multi-threaded, use of fork() may lead to deadlocks in the child.
[2025-02-13T04:11:00.381+0000] {standard_task_runner.py:72} INFO - Started process 1390 to run task
[2025-02-13T04:11:00.379+0000] {standard_task_runner.py:104} INFO - Running: ['airflow', 'tasks', 'run', 'transform_data_dag', 'dbt_run', 'manual__2025-02-13T04:10:58.490297+00:00', '--job-id', '20', '--raw', '--subdir', 'DAGS_FOLDER/transform_data_dag.py', '--cfg-path', '/tmp/tmp4rzai5jh']
[2025-02-13T04:11:00.383+0000] {standard_task_runner.py:105} INFO - Job 20: Subtask dbt_run
[2025-02-13T04:11:00.402+0000] {logging_mixin.py:190} WARNING - /home/airflow/.local/lib/python3.12/site-packages/airflow/settings.py:209 DeprecationWarning: The sql_alchemy_conn option in [core] has been moved to the sql_alchemy_conn option in [database] - the old setting has been used, but please update your config.
[2025-02-13T04:11:00.439+0000] {task_command.py:467} INFO - Running <TaskInstance: transform_data_dag.dbt_run manual__2025-02-13T04:10:58.490297+00:00 [running]> on host 1202205ac05f
[2025-02-13T04:11:00.495+0000] {logging_mixin.py:190} WARNING - /home/airflow/.local/lib/python3.12/site-packages/airflow/utils/log/secrets_masker.py:84 DeprecationWarning: The sensitive_variable_fields option in [admin] has been moved to the sensitive_var_conn_names option in [core] - the old setting has been used, but please update your config.
[2025-02-13T04:11:00.529+0000] {taskinstance.py:3134} INFO - Exporting env vars: AIRFLOW_CTX_DAG_OWNER='airflow' AIRFLOW_CTX_DAG_ID='transform_data_dag' AIRFLOW_CTX_TASK_ID='dbt_run' AIRFLOW_CTX_EXECUTION_DATE='2025-02-13T04:10:58.490297+00:00' AIRFLOW_CTX_TRY_NUMBER='1' AIRFLOW_CTX_DAG_RUN_ID='manual__2025-02-13T04:10:58.490297+00:00'
[2025-02-13T04:11:00.530+0000] {taskinstance.py:732} INFO - ::endgroup::
[2025-02-13T04:11:00.550+0000] {subprocess.py:78} INFO - Tmp dir root location: /tmp
[2025-02-13T04:11:00.552+0000] {subprocess.py:88} INFO - Running command: ['/usr/bin/bash', '-c', 'cd /opt/airflow/dags/dbt && dbt run']
[2025-02-13T04:11:00.560+0000] {subprocess.py:99} INFO - Output:
[2025-02-13T04:11:03.887+0000] {subprocess.py:106} INFO - [0m04:11:03  Running with dbt=1.8.7
[2025-02-13T04:11:03.890+0000] {subprocess.py:106} INFO - [0m04:11:03  Encountered an error:
[2025-02-13T04:11:03.891+0000] {subprocess.py:106} INFO - Runtime Error
[2025-02-13T04:11:03.891+0000] {subprocess.py:106} INFO -   No dbt_project.yml found at expected path /opt/airflow/dags/dbt/dbt_project.yml
[2025-02-13T04:11:03.892+0000] {subprocess.py:106} INFO -   Verify that each entry within packages.yml (and their transitive dependencies) contains a file named dbt_project.yml
[2025-02-13T04:11:03.893+0000] {subprocess.py:106} INFO - 
[2025-02-13T04:11:04.930+0000] {subprocess.py:110} INFO - Command exited with return code 2
[2025-02-13T04:11:04.950+0000] {taskinstance.py:3313} ERROR - Task failed with exception
Traceback (most recent call last):
  File "/home/airflow/.local/lib/python3.12/site-packages/airflow/models/taskinstance.py", line 768, in _execute_task
    result = _execute_callable(context=context, **execute_callable_kwargs)
             ^^^^^^^^^^^^^^^^^^^^^^^^^^^^^^^^^^^^^^^^^^^^^^^^^^^^^^^^^^^^^
  File "/home/airflow/.local/lib/python3.12/site-packages/airflow/models/taskinstance.py", line 734, in _execute_callable
    return ExecutionCallableRunner(
           ^^^^^^^^^^^^^^^^^^^^^^^^
  File "/home/airflow/.local/lib/python3.12/site-packages/airflow/utils/operator_helpers.py", line 252, in run
    return self.func(*args, **kwargs)
           ^^^^^^^^^^^^^^^^^^^^^^^^^^
  File "/home/airflow/.local/lib/python3.12/site-packages/airflow/models/baseoperator.py", line 424, in wrapper
    return func(self, *args, **kwargs)
           ^^^^^^^^^^^^^^^^^^^^^^^^^^^
  File "/home/airflow/.local/lib/python3.12/site-packages/airflow/operators/bash.py", line 276, in execute
    raise AirflowException(
airflow.exceptions.AirflowException: Bash command failed. The command returned a non-zero exit code 2.
[2025-02-13T04:11:04.956+0000] {taskinstance.py:1226} INFO - Marking task as FAILED. dag_id=transform_data_dag, task_id=dbt_run, run_id=manual__2025-02-13T04:10:58.490297+00:00, execution_date=20250213T041058, start_date=20250213T041100, end_date=20250213T041104
[2025-02-13T04:11:04.987+0000] {taskinstance.py:341} INFO - ::group::Post task execution logs
[2025-02-13T04:11:04.988+0000] {standard_task_runner.py:124} ERROR - Failed to execute job 20 for task dbt_run (Bash command failed. The command returned a non-zero exit code 2.; 1390)
Traceback (most recent call last):
  File "/home/airflow/.local/lib/python3.12/site-packages/airflow/task/task_runner/standard_task_runner.py", line 117, in _start_by_fork
    ret = args.func(args, dag=self.dag)
          ^^^^^^^^^^^^^^^^^^^^^^^^^^^^^
  File "/home/airflow/.local/lib/python3.12/site-packages/airflow/cli/cli_config.py", line 49, in command
    return func(*args, **kwargs)
           ^^^^^^^^^^^^^^^^^^^^^
  File "/home/airflow/.local/lib/python3.12/site-packages/airflow/utils/cli.py", line 116, in wrapper
    return f(*args, **kwargs)
           ^^^^^^^^^^^^^^^^^^
  File "/home/airflow/.local/lib/python3.12/site-packages/airflow/cli/commands/task_command.py", line 483, in task_run
    task_return_code = _run_task_by_selected_method(args, _dag, ti)
                       ^^^^^^^^^^^^^^^^^^^^^^^^^^^^^^^^^^^^^^^^^^^^
  File "/home/airflow/.local/lib/python3.12/site-packages/airflow/cli/commands/task_command.py", line 256, in _run_task_by_selected_method
    return _run_raw_task(args, ti)
           ^^^^^^^^^^^^^^^^^^^^^^^
  File "/home/airflow/.local/lib/python3.12/site-packages/airflow/cli/commands/task_command.py", line 341, in _run_raw_task
    return ti._run_raw_task(
           ^^^^^^^^^^^^^^^^^
  File "/home/airflow/.local/lib/python3.12/site-packages/airflow/utils/session.py", line 97, in wrapper
    return func(*args, session=session, **kwargs)
           ^^^^^^^^^^^^^^^^^^^^^^^^^^^^^^^^^^^^^^
  File "/home/airflow/.local/lib/python3.12/site-packages/airflow/models/taskinstance.py", line 3006, in _run_raw_task
    return _run_raw_task(
           ^^^^^^^^^^^^^^
  File "/home/airflow/.local/lib/python3.12/site-packages/airflow/models/taskinstance.py", line 274, in _run_raw_task
    TaskInstance._execute_task_with_callbacks(
  File "/home/airflow/.local/lib/python3.12/site-packages/airflow/models/taskinstance.py", line 3161, in _execute_task_with_callbacks
    result = self._execute_task(context, task_orig)
             ^^^^^^^^^^^^^^^^^^^^^^^^^^^^^^^^^^^^^^
  File "/home/airflow/.local/lib/python3.12/site-packages/airflow/models/taskinstance.py", line 3185, in _execute_task
    return _execute_task(self, context, task_orig)
           ^^^^^^^^^^^^^^^^^^^^^^^^^^^^^^^^^^^^^^^
  File "/home/airflow/.local/lib/python3.12/site-packages/airflow/models/taskinstance.py", line 768, in _execute_task
    result = _execute_callable(context=context, **execute_callable_kwargs)
             ^^^^^^^^^^^^^^^^^^^^^^^^^^^^^^^^^^^^^^^^^^^^^^^^^^^^^^^^^^^^^
  File "/home/airflow/.local/lib/python3.12/site-packages/airflow/models/taskinstance.py", line 734, in _execute_callable
    return ExecutionCallableRunner(
           ^^^^^^^^^^^^^^^^^^^^^^^^
  File "/home/airflow/.local/lib/python3.12/site-packages/airflow/utils/operator_helpers.py", line 252, in run
    return self.func(*args, **kwargs)
           ^^^^^^^^^^^^^^^^^^^^^^^^^^
  File "/home/airflow/.local/lib/python3.12/site-packages/airflow/models/baseoperator.py", line 424, in wrapper
    return func(self, *args, **kwargs)
           ^^^^^^^^^^^^^^^^^^^^^^^^^^^
  File "/home/airflow/.local/lib/python3.12/site-packages/airflow/operators/bash.py", line 276, in execute
    raise AirflowException(
airflow.exceptions.AirflowException: Bash command failed. The command returned a non-zero exit code 2.
[2025-02-13T04:11:05.015+0000] {local_task_job_runner.py:266} INFO - Task exited with return code 1
[2025-02-13T04:11:05.042+0000] {taskinstance.py:3901} INFO - 0 downstream tasks scheduled from follow-on schedule check
[2025-02-13T04:11:05.047+0000] {local_task_job_runner.py:245} INFO - ::endgroup::
