[2025-02-13T08:26:04.179+0000] {local_task_job_runner.py:123} INFO - ::group::Pre task execution logs
[2025-02-13T08:26:04.202+0000] {taskinstance.py:2614} INFO - Dependencies all met for dep_context=non-requeueable deps ti=<TaskInstance: transform_data_dag.dbt_run manual__2025-02-13T08:25:56.917849+00:00 [queued]>
[2025-02-13T08:26:04.214+0000] {taskinstance.py:2614} INFO - Dependencies all met for dep_context=requeueable deps ti=<TaskInstance: transform_data_dag.dbt_run manual__2025-02-13T08:25:56.917849+00:00 [queued]>
[2025-02-13T08:26:04.215+0000] {taskinstance.py:2867} INFO - Starting attempt 1 of 1
[2025-02-13T08:26:04.230+0000] {taskinstance.py:2890} INFO - Executing <Task(BashOperator): dbt_run> on 2025-02-13 08:25:56.917849+00:00
[2025-02-13T08:26:04.236+0000] {logging_mixin.py:190} WARNING - /home/airflow/.local/lib/python3.12/site-packages/airflow/task/task_runner/standard_task_runner.py:70 DeprecationWarning: This process (pid=6063) is multi-threaded, use of fork() may lead to deadlocks in the child.
[2025-02-13T08:26:04.238+0000] {standard_task_runner.py:72} INFO - Started process 6064 to run task
[2025-02-13T08:26:04.237+0000] {standard_task_runner.py:104} INFO - Running: ['airflow', 'tasks', 'run', 'transform_data_dag', 'dbt_run', 'manual__2025-02-13T08:25:56.917849+00:00', '--job-id', '75', '--raw', '--subdir', 'DAGS_FOLDER/transform_data_dag.py', '--cfg-path', '/tmp/tmpnwddczn8']
[2025-02-13T08:26:04.240+0000] {standard_task_runner.py:105} INFO - Job 75: Subtask dbt_run
[2025-02-13T08:26:04.262+0000] {logging_mixin.py:190} WARNING - /home/airflow/.local/lib/python3.12/site-packages/airflow/settings.py:209 DeprecationWarning: The sql_alchemy_conn option in [core] has been moved to the sql_alchemy_conn option in [database] - the old setting has been used, but please update your config.
[2025-02-13T08:26:04.297+0000] {task_command.py:467} INFO - Running <TaskInstance: transform_data_dag.dbt_run manual__2025-02-13T08:25:56.917849+00:00 [running]> on host 89bb8c6379b5
[2025-02-13T08:26:04.357+0000] {logging_mixin.py:190} WARNING - /home/airflow/.local/lib/python3.12/site-packages/airflow/utils/log/secrets_masker.py:84 DeprecationWarning: The sensitive_variable_fields option in [admin] has been moved to the sensitive_var_conn_names option in [core] - the old setting has been used, but please update your config.
[2025-02-13T08:26:04.389+0000] {taskinstance.py:3134} INFO - Exporting env vars: AIRFLOW_CTX_DAG_OWNER='airflow' AIRFLOW_CTX_DAG_ID='transform_data_dag' AIRFLOW_CTX_TASK_ID='dbt_run' AIRFLOW_CTX_EXECUTION_DATE='2025-02-13T08:25:56.917849+00:00' AIRFLOW_CTX_TRY_NUMBER='1' AIRFLOW_CTX_DAG_RUN_ID='manual__2025-02-13T08:25:56.917849+00:00'
[2025-02-13T08:26:04.390+0000] {taskinstance.py:732} INFO - ::endgroup::
[2025-02-13T08:26:04.408+0000] {subprocess.py:78} INFO - Tmp dir root location: /tmp
[2025-02-13T08:26:04.409+0000] {subprocess.py:88} INFO - Running command: ['/usr/bin/bash', '-c', 'cd /opt/airflow/dags/dbt/***_project && dbt run']
[2025-02-13T08:26:04.417+0000] {subprocess.py:99} INFO - Output:
[2025-02-13T08:26:06.771+0000] {subprocess.py:106} INFO - [0m08:26:06  Running with dbt=1.8.7
[2025-02-13T08:26:07.106+0000] {subprocess.py:106} INFO - [0m08:26:07  Registered adapter: ***=1.9.0
[2025-02-13T08:26:07.827+0000] {subprocess.py:106} INFO - [0m08:26:07  Found 6 models, 2 data tests, 3 sources, 429 macros
[2025-02-13T08:26:07.831+0000] {subprocess.py:106} INFO - [0m08:26:07
[2025-02-13T08:26:07.955+0000] {subprocess.py:106} INFO - [0m08:26:07  Concurrency: 1 threads (target='dev')
[2025-02-13T08:26:07.956+0000] {subprocess.py:106} INFO - [0m08:26:07
[2025-02-13T08:26:08.035+0000] {subprocess.py:106} INFO - [0m08:26:08  1 of 3 START sql incremental model model.order_items ........................... [RUN]
[2025-02-13T08:26:08.217+0000] {subprocess.py:106} INFO - [0m08:26:08  1 of 3 ERROR creating sql incremental model model.order_items .................. [[31mERROR[0m in 0.18s]
[2025-02-13T08:26:08.221+0000] {subprocess.py:106} INFO - [0m08:26:08  2 of 3 START sql incremental model model.orders ................................ [RUN]
[2025-02-13T08:26:08.304+0000] {subprocess.py:106} INFO - [0m08:26:08  2 of 3 OK created sql incremental model model.orders ........................... [[32mSELECT 10[0m in 0.08s]
[2025-02-13T08:26:08.308+0000] {subprocess.py:106} INFO - [0m08:26:08  3 of 3 START sql incremental model model.products .............................. [RUN]
[2025-02-13T08:26:08.399+0000] {subprocess.py:106} INFO - [0m08:26:08  3 of 3 OK created sql incremental model model.products ......................... [[32mSELECT 16[0m in 0.09s]
[2025-02-13T08:26:08.417+0000] {subprocess.py:106} INFO - [0m08:26:08
[2025-02-13T08:26:08.418+0000] {subprocess.py:106} INFO - [0m08:26:08  Finished running 3 incremental models in 0 hours 0 minutes and 0.58 seconds (0.58s).
[2025-02-13T08:26:08.500+0000] {subprocess.py:106} INFO - [0m08:26:08
[2025-02-13T08:26:08.501+0000] {subprocess.py:106} INFO - [0m08:26:08  [31mCompleted with 1 error and 0 warnings:[0m
[2025-02-13T08:26:08.502+0000] {subprocess.py:106} INFO - [0m08:26:08
[2025-02-13T08:26:08.503+0000] {subprocess.py:106} INFO - [0m08:26:08    Database Error in model order_items (models/cleansed/order_items.sql)
[2025-02-13T08:26:08.504+0000] {subprocess.py:106} INFO -   relation "model.products" does not exist
[2025-02-13T08:26:08.504+0000] {subprocess.py:106} INFO -   compiled code at target/run/***_project/models/cleansed/order_items.sql
[2025-02-13T08:26:08.505+0000] {subprocess.py:106} INFO - [0m08:26:08
[2025-02-13T08:26:08.506+0000] {subprocess.py:106} INFO - [0m08:26:08  Done. PASS=2 WARN=0 ERROR=1 SKIP=0 TOTAL=3
[2025-02-13T08:26:09.227+0000] {subprocess.py:110} INFO - Command exited with return code 1
[2025-02-13T08:26:09.239+0000] {taskinstance.py:3313} ERROR - Task failed with exception
Traceback (most recent call last):
  File "/home/airflow/.local/lib/python3.12/site-packages/airflow/models/taskinstance.py", line 768, in _execute_task
    result = _execute_callable(context=context, **execute_callable_kwargs)
             ^^^^^^^^^^^^^^^^^^^^^^^^^^^^^^^^^^^^^^^^^^^^^^^^^^^^^^^^^^^^^
  File "/home/airflow/.local/lib/python3.12/site-packages/airflow/models/taskinstance.py", line 734, in _execute_callable
    return ExecutionCallableRunner(
           ^^^^^^^^^^^^^^^^^^^^^^^^
  File "/home/airflow/.local/lib/python3.12/site-packages/airflow/utils/operator_helpers.py", line 252, in run
    return self.func(*args, **kwargs)
           ^^^^^^^^^^^^^^^^^^^^^^^^^^
  File "/home/airflow/.local/lib/python3.12/site-packages/airflow/models/baseoperator.py", line 424, in wrapper
    return func(self, *args, **kwargs)
           ^^^^^^^^^^^^^^^^^^^^^^^^^^^
  File "/home/airflow/.local/lib/python3.12/site-packages/airflow/operators/bash.py", line 276, in execute
    raise AirflowException(
airflow.exceptions.AirflowException: Bash command failed. The command returned a non-zero exit code 1.
[2025-02-13T08:26:09.244+0000] {taskinstance.py:1226} INFO - Marking task as FAILED. dag_id=transform_data_dag, task_id=dbt_run, run_id=manual__2025-02-13T08:25:56.917849+00:00, execution_date=20250213T082556, start_date=20250213T082604, end_date=20250213T082609
[2025-02-13T08:26:09.272+0000] {taskinstance.py:341} INFO - ::group::Post task execution logs
[2025-02-13T08:26:09.273+0000] {standard_task_runner.py:124} ERROR - Failed to execute job 75 for task dbt_run (Bash command failed. The command returned a non-zero exit code 1.; 6064)
Traceback (most recent call last):
  File "/home/airflow/.local/lib/python3.12/site-packages/airflow/task/task_runner/standard_task_runner.py", line 117, in _start_by_fork
    ret = args.func(args, dag=self.dag)
          ^^^^^^^^^^^^^^^^^^^^^^^^^^^^^
  File "/home/airflow/.local/lib/python3.12/site-packages/airflow/cli/cli_config.py", line 49, in command
    return func(*args, **kwargs)
           ^^^^^^^^^^^^^^^^^^^^^
  File "/home/airflow/.local/lib/python3.12/site-packages/airflow/utils/cli.py", line 116, in wrapper
    return f(*args, **kwargs)
           ^^^^^^^^^^^^^^^^^^
  File "/home/airflow/.local/lib/python3.12/site-packages/airflow/cli/commands/task_command.py", line 483, in task_run
    task_return_code = _run_task_by_selected_method(args, _dag, ti)
                       ^^^^^^^^^^^^^^^^^^^^^^^^^^^^^^^^^^^^^^^^^^^^
  File "/home/airflow/.local/lib/python3.12/site-packages/airflow/cli/commands/task_command.py", line 256, in _run_task_by_selected_method
    return _run_raw_task(args, ti)
           ^^^^^^^^^^^^^^^^^^^^^^^
  File "/home/airflow/.local/lib/python3.12/site-packages/airflow/cli/commands/task_command.py", line 341, in _run_raw_task
    return ti._run_raw_task(
           ^^^^^^^^^^^^^^^^^
  File "/home/airflow/.local/lib/python3.12/site-packages/airflow/utils/session.py", line 97, in wrapper
    return func(*args, session=session, **kwargs)
           ^^^^^^^^^^^^^^^^^^^^^^^^^^^^^^^^^^^^^^
  File "/home/airflow/.local/lib/python3.12/site-packages/airflow/models/taskinstance.py", line 3006, in _run_raw_task
    return _run_raw_task(
           ^^^^^^^^^^^^^^
  File "/home/airflow/.local/lib/python3.12/site-packages/airflow/models/taskinstance.py", line 274, in _run_raw_task
    TaskInstance._execute_task_with_callbacks(
  File "/home/airflow/.local/lib/python3.12/site-packages/airflow/models/taskinstance.py", line 3161, in _execute_task_with_callbacks
    result = self._execute_task(context, task_orig)
             ^^^^^^^^^^^^^^^^^^^^^^^^^^^^^^^^^^^^^^
  File "/home/airflow/.local/lib/python3.12/site-packages/airflow/models/taskinstance.py", line 3185, in _execute_task
    return _execute_task(self, context, task_orig)
           ^^^^^^^^^^^^^^^^^^^^^^^^^^^^^^^^^^^^^^^
  File "/home/airflow/.local/lib/python3.12/site-packages/airflow/models/taskinstance.py", line 768, in _execute_task
    result = _execute_callable(context=context, **execute_callable_kwargs)
             ^^^^^^^^^^^^^^^^^^^^^^^^^^^^^^^^^^^^^^^^^^^^^^^^^^^^^^^^^^^^^
  File "/home/airflow/.local/lib/python3.12/site-packages/airflow/models/taskinstance.py", line 734, in _execute_callable
    return ExecutionCallableRunner(
           ^^^^^^^^^^^^^^^^^^^^^^^^
  File "/home/airflow/.local/lib/python3.12/site-packages/airflow/utils/operator_helpers.py", line 252, in run
    return self.func(*args, **kwargs)
           ^^^^^^^^^^^^^^^^^^^^^^^^^^
  File "/home/airflow/.local/lib/python3.12/site-packages/airflow/models/baseoperator.py", line 424, in wrapper
    return func(self, *args, **kwargs)
           ^^^^^^^^^^^^^^^^^^^^^^^^^^^
  File "/home/airflow/.local/lib/python3.12/site-packages/airflow/operators/bash.py", line 276, in execute
    raise AirflowException(
airflow.exceptions.AirflowException: Bash command failed. The command returned a non-zero exit code 1.
[2025-02-13T08:26:09.303+0000] {local_task_job_runner.py:266} INFO - Task exited with return code 1
[2025-02-13T08:26:09.326+0000] {taskinstance.py:3901} INFO - 0 downstream tasks scheduled from follow-on schedule check
[2025-02-13T08:26:09.331+0000] {local_task_job_runner.py:245} INFO - ::endgroup::
