[2025-02-13T06:31:57.994+0000] {local_task_job_runner.py:123} INFO - ::group::Pre task execution logs
[2025-02-13T06:31:58.017+0000] {taskinstance.py:2614} INFO - Dependencies all met for dep_context=non-requeueable deps ti=<TaskInstance: transform_data_dag.dbt_run manual__2025-02-13T06:31:56.145505+00:00 [queued]>
[2025-02-13T06:31:58.029+0000] {taskinstance.py:2614} INFO - Dependencies all met for dep_context=requeueable deps ti=<TaskInstance: transform_data_dag.dbt_run manual__2025-02-13T06:31:56.145505+00:00 [queued]>
[2025-02-13T06:31:58.031+0000] {taskinstance.py:2867} INFO - Starting attempt 1 of 1
[2025-02-13T06:31:58.047+0000] {taskinstance.py:2890} INFO - Executing <Task(BashOperator): dbt_run> on 2025-02-13 06:31:56.145505+00:00
[2025-02-13T06:31:58.054+0000] {logging_mixin.py:190} WARNING - /home/airflow/.local/lib/python3.12/site-packages/airflow/task/task_runner/standard_task_runner.py:70 DeprecationWarning: This process (pid=3186) is multi-threaded, use of fork() may lead to deadlocks in the child.
[2025-02-13T06:31:58.054+0000] {standard_task_runner.py:104} INFO - Running: ['airflow', 'tasks', 'run', 'transform_data_dag', 'dbt_run', 'manual__2025-02-13T06:31:56.145505+00:00', '--job-id', '31', '--raw', '--subdir', 'DAGS_FOLDER/transform_data_dag.py', '--cfg-path', '/tmp/tmp9_jolhfm']
[2025-02-13T06:31:58.056+0000] {standard_task_runner.py:72} INFO - Started process 3187 to run task
[2025-02-13T06:31:58.057+0000] {standard_task_runner.py:105} INFO - Job 31: Subtask dbt_run
[2025-02-13T06:31:58.079+0000] {logging_mixin.py:190} WARNING - /home/airflow/.local/lib/python3.12/site-packages/airflow/settings.py:209 DeprecationWarning: The sql_alchemy_conn option in [core] has been moved to the sql_alchemy_conn option in [database] - the old setting has been used, but please update your config.
[2025-02-13T06:31:58.118+0000] {task_command.py:467} INFO - Running <TaskInstance: transform_data_dag.dbt_run manual__2025-02-13T06:31:56.145505+00:00 [running]> on host 89bb8c6379b5
[2025-02-13T06:31:58.180+0000] {logging_mixin.py:190} WARNING - /home/airflow/.local/lib/python3.12/site-packages/airflow/utils/log/secrets_masker.py:84 DeprecationWarning: The sensitive_variable_fields option in [admin] has been moved to the sensitive_var_conn_names option in [core] - the old setting has been used, but please update your config.
[2025-02-13T06:31:58.215+0000] {taskinstance.py:3134} INFO - Exporting env vars: AIRFLOW_CTX_DAG_OWNER='airflow' AIRFLOW_CTX_DAG_ID='transform_data_dag' AIRFLOW_CTX_TASK_ID='dbt_run' AIRFLOW_CTX_EXECUTION_DATE='2025-02-13T06:31:56.145505+00:00' AIRFLOW_CTX_TRY_NUMBER='1' AIRFLOW_CTX_DAG_RUN_ID='manual__2025-02-13T06:31:56.145505+00:00'
[2025-02-13T06:31:58.216+0000] {taskinstance.py:732} INFO - ::endgroup::
[2025-02-13T06:31:58.234+0000] {subprocess.py:78} INFO - Tmp dir root location: /tmp
[2025-02-13T06:31:58.236+0000] {subprocess.py:88} INFO - Running command: ['/usr/bin/bash', '-c', 'cd /opt/airflow/dags/dbt/***_project && dbt run']
[2025-02-13T06:31:58.243+0000] {subprocess.py:99} INFO - Output:
[2025-02-13T06:32:00.649+0000] {subprocess.py:106} INFO - [0m06:32:00  Running with dbt=1.8.7
[2025-02-13T06:32:01.009+0000] {subprocess.py:106} INFO - [0m06:32:01  Registered adapter: ***=1.9.0
[2025-02-13T06:32:01.240+0000] {subprocess.py:106} INFO - [0m06:32:01  Unable to do partial parsing because profile has changed
[2025-02-13T06:32:01.241+0000] {subprocess.py:106} INFO - [0m06:32:01  Unable to do partial parsing because a project config has changed
[2025-02-13T06:32:03.102+0000] {subprocess.py:106} INFO - [0m06:32:03  Found 4 models, 4 sources, 429 macros
[2025-02-13T06:32:03.107+0000] {subprocess.py:106} INFO - [0m06:32:03
[2025-02-13T06:32:03.279+0000] {subprocess.py:106} INFO - [0m06:32:03  Concurrency: 1 threads (target='dev')
[2025-02-13T06:32:03.280+0000] {subprocess.py:106} INFO - [0m06:32:03
[2025-02-13T06:32:03.354+0000] {subprocess.py:106} INFO - [0m06:32:03  1 of 1 START sql incremental model model.products .............................. [RUN]
[2025-02-13T06:32:03.500+0000] {subprocess.py:106} INFO - [0m06:32:03  1 of 1 ERROR creating sql incremental model model.products ..................... [[31mERROR[0m in 0.14s]
[2025-02-13T06:32:03.520+0000] {subprocess.py:106} INFO - [0m06:32:03
[2025-02-13T06:32:03.521+0000] {subprocess.py:106} INFO - [0m06:32:03  Finished running 1 incremental model in 0 hours 0 minutes and 0.41 seconds (0.41s).
[2025-02-13T06:32:03.597+0000] {subprocess.py:106} INFO - [0m06:32:03
[2025-02-13T06:32:03.598+0000] {subprocess.py:106} INFO - [0m06:32:03  [31mCompleted with 1 error and 0 warnings:[0m
[2025-02-13T06:32:03.599+0000] {subprocess.py:106} INFO - [0m06:32:03
[2025-02-13T06:32:03.600+0000] {subprocess.py:106} INFO - [0m06:32:03    Database Error in model products (models/cleansed/products.sql)
[2025-02-13T06:32:03.600+0000] {subprocess.py:106} INFO -   relation "raw.raw_products" does not exist
[2025-02-13T06:32:03.601+0000] {subprocess.py:106} INFO -   LINE 17:     select * from "airflow"."raw"."raw_products"
[2025-02-13T06:32:03.602+0000] {subprocess.py:106} INFO -                              ^
[2025-02-13T06:32:03.604+0000] {subprocess.py:106} INFO - [0m06:32:03
[2025-02-13T06:32:03.604+0000] {subprocess.py:106} INFO - [0m06:32:03  Done. PASS=0 WARN=0 ERROR=1 SKIP=0 TOTAL=1
[2025-02-13T06:32:04.402+0000] {subprocess.py:110} INFO - Command exited with return code 1
[2025-02-13T06:32:04.413+0000] {taskinstance.py:3313} ERROR - Task failed with exception
Traceback (most recent call last):
  File "/home/airflow/.local/lib/python3.12/site-packages/airflow/models/taskinstance.py", line 768, in _execute_task
    result = _execute_callable(context=context, **execute_callable_kwargs)
             ^^^^^^^^^^^^^^^^^^^^^^^^^^^^^^^^^^^^^^^^^^^^^^^^^^^^^^^^^^^^^
  File "/home/airflow/.local/lib/python3.12/site-packages/airflow/models/taskinstance.py", line 734, in _execute_callable
    return ExecutionCallableRunner(
           ^^^^^^^^^^^^^^^^^^^^^^^^
  File "/home/airflow/.local/lib/python3.12/site-packages/airflow/utils/operator_helpers.py", line 252, in run
    return self.func(*args, **kwargs)
           ^^^^^^^^^^^^^^^^^^^^^^^^^^
  File "/home/airflow/.local/lib/python3.12/site-packages/airflow/models/baseoperator.py", line 424, in wrapper
    return func(self, *args, **kwargs)
           ^^^^^^^^^^^^^^^^^^^^^^^^^^^
  File "/home/airflow/.local/lib/python3.12/site-packages/airflow/operators/bash.py", line 276, in execute
    raise AirflowException(
airflow.exceptions.AirflowException: Bash command failed. The command returned a non-zero exit code 1.
[2025-02-13T06:32:04.420+0000] {taskinstance.py:1226} INFO - Marking task as FAILED. dag_id=transform_data_dag, task_id=dbt_run, run_id=manual__2025-02-13T06:31:56.145505+00:00, execution_date=20250213T063156, start_date=20250213T063158, end_date=20250213T063204
[2025-02-13T06:32:04.448+0000] {taskinstance.py:341} INFO - ::group::Post task execution logs
[2025-02-13T06:32:04.449+0000] {standard_task_runner.py:124} ERROR - Failed to execute job 31 for task dbt_run (Bash command failed. The command returned a non-zero exit code 1.; 3187)
Traceback (most recent call last):
  File "/home/airflow/.local/lib/python3.12/site-packages/airflow/task/task_runner/standard_task_runner.py", line 117, in _start_by_fork
    ret = args.func(args, dag=self.dag)
          ^^^^^^^^^^^^^^^^^^^^^^^^^^^^^
  File "/home/airflow/.local/lib/python3.12/site-packages/airflow/cli/cli_config.py", line 49, in command
    return func(*args, **kwargs)
           ^^^^^^^^^^^^^^^^^^^^^
  File "/home/airflow/.local/lib/python3.12/site-packages/airflow/utils/cli.py", line 116, in wrapper
    return f(*args, **kwargs)
           ^^^^^^^^^^^^^^^^^^
  File "/home/airflow/.local/lib/python3.12/site-packages/airflow/cli/commands/task_command.py", line 483, in task_run
    task_return_code = _run_task_by_selected_method(args, _dag, ti)
                       ^^^^^^^^^^^^^^^^^^^^^^^^^^^^^^^^^^^^^^^^^^^^
  File "/home/airflow/.local/lib/python3.12/site-packages/airflow/cli/commands/task_command.py", line 256, in _run_task_by_selected_method
    return _run_raw_task(args, ti)
           ^^^^^^^^^^^^^^^^^^^^^^^
  File "/home/airflow/.local/lib/python3.12/site-packages/airflow/cli/commands/task_command.py", line 341, in _run_raw_task
    return ti._run_raw_task(
           ^^^^^^^^^^^^^^^^^
  File "/home/airflow/.local/lib/python3.12/site-packages/airflow/utils/session.py", line 97, in wrapper
    return func(*args, session=session, **kwargs)
           ^^^^^^^^^^^^^^^^^^^^^^^^^^^^^^^^^^^^^^
  File "/home/airflow/.local/lib/python3.12/site-packages/airflow/models/taskinstance.py", line 3006, in _run_raw_task
    return _run_raw_task(
           ^^^^^^^^^^^^^^
  File "/home/airflow/.local/lib/python3.12/site-packages/airflow/models/taskinstance.py", line 274, in _run_raw_task
    TaskInstance._execute_task_with_callbacks(
  File "/home/airflow/.local/lib/python3.12/site-packages/airflow/models/taskinstance.py", line 3161, in _execute_task_with_callbacks
    result = self._execute_task(context, task_orig)
             ^^^^^^^^^^^^^^^^^^^^^^^^^^^^^^^^^^^^^^
  File "/home/airflow/.local/lib/python3.12/site-packages/airflow/models/taskinstance.py", line 3185, in _execute_task
    return _execute_task(self, context, task_orig)
           ^^^^^^^^^^^^^^^^^^^^^^^^^^^^^^^^^^^^^^^
  File "/home/airflow/.local/lib/python3.12/site-packages/airflow/models/taskinstance.py", line 768, in _execute_task
    result = _execute_callable(context=context, **execute_callable_kwargs)
             ^^^^^^^^^^^^^^^^^^^^^^^^^^^^^^^^^^^^^^^^^^^^^^^^^^^^^^^^^^^^^
  File "/home/airflow/.local/lib/python3.12/site-packages/airflow/models/taskinstance.py", line 734, in _execute_callable
    return ExecutionCallableRunner(
           ^^^^^^^^^^^^^^^^^^^^^^^^
  File "/home/airflow/.local/lib/python3.12/site-packages/airflow/utils/operator_helpers.py", line 252, in run
    return self.func(*args, **kwargs)
           ^^^^^^^^^^^^^^^^^^^^^^^^^^
  File "/home/airflow/.local/lib/python3.12/site-packages/airflow/models/baseoperator.py", line 424, in wrapper
    return func(self, *args, **kwargs)
           ^^^^^^^^^^^^^^^^^^^^^^^^^^^
  File "/home/airflow/.local/lib/python3.12/site-packages/airflow/operators/bash.py", line 276, in execute
    raise AirflowException(
airflow.exceptions.AirflowException: Bash command failed. The command returned a non-zero exit code 1.
[2025-02-13T06:32:04.463+0000] {local_task_job_runner.py:266} INFO - Task exited with return code 1
[2025-02-13T06:32:04.487+0000] {taskinstance.py:3901} INFO - 0 downstream tasks scheduled from follow-on schedule check
[2025-02-13T06:32:04.492+0000] {local_task_job_runner.py:245} INFO - ::endgroup::
